Workbook

Sheet Source Results
F5: Seed 42 | J5: Seed 63 | N5: Seed 84
B7: Cluster | C7: Test Samples | D7: GP | E7: RF | F7: Test Samples | G7: MAE | H7: GP | I7: RF | J7: Test Samples | K7: MAE | L7: GP | M7: RF | N7: Test Samples | O7: MAE | P7: GP | Q7: RF
B8: 0 | C8: =AVERAGE(F8,J8,N8) -> 2681.6667 | D8: =AVERAGE(H8,L8,P8) -> 3.93 | E8: =AVERAGE(I8,M8,Q8) -> 4.2566667 | F8: 2680 | G8: 24.8 | H8: 3.83 | I8: 3.78 | J8: 3305 | K8: 28.1 | L8: 4.15 | M8: 4.65 | N8: 2060 | O8: 25.9 | P8: 3.81 | Q8: 4.34
B9: 1 | C9: =AVERAGE(F9,J9,N9) -> 2845 | D9: =AVERAGE(H9,L9,P9) -> 3.3833333 | E9: =AVERAGE(I9,M9,Q9) -> 3.73 | F9: 3155 | G9: 24.7 | H9: 3.68 | I9: 3.89 | J9: 2985 | K9: 22.1 | L9: 3.47 | M9: 3.79 | N9: 2395 | O9: 19.8 | P9: 3 | Q9: 3.51
B10: 2 | C10: =AVERAGE(F10,J10,N10) -> 2110 | D10: =AVERAGE(H10,L10,P10) -> 3.32 | E10: =AVERAGE(I10,M10,Q10) -> 3.4666667 | F10: 2140 | G10: 26.7 | H10: 3.85 | I10: 4.24 | J10: 1895 | K10: 20.5 | L10: 3.03 | M10: 3.12 | N10: 2295 | O10: 18.9 | P10: 3.08 | Q10: 3.04
B11: 3 | C11: =AVERAGE(F11,J11,N11) -> 2228.3333 | D11: =AVERAGE(H11,L11,P11) -> 3.7633333 | E11: =AVERAGE(I11,M11,Q11) -> 4.1366667 | F11: 1420 | G11: 26.3 | H11: 3.86 | I11: 4.6 | J11: 2430 | K11: 24.8 | L11: 3.68 | M11: 3.8 | N11: 2835 | O11: 25.1 | P11: 3.75 | Q11: 4.01
B12: 4 | C12: =AVERAGE(F12,J12,N12) -> 2186.6667 | D12: =AVERAGE(H12,L12,P12) -> 3.97 | E12: =AVERAGE(I12,M12,Q12) -> 4.2566667 | F12: 2805 | G12: 24.4 | H12: 3.74 | I12: 4.27 | J12: 1405 | K12: 25.7 | L12: 3.99 | M12: 3.97 | N12: 2350 | O12: 27.8 | P12: 4.18 | Q12: 4.53
B13: 5 | C13: =AVERAGE(F13,J13,N13) -> 2170 | D13: =AVERAGE(H13,L13,P13) -> 3.4433333 | E13: =AVERAGE(I13,M13,Q13) -> 3.7833333 | F13: 2015 | G13: 18.3 | H13: 2.77 | I13: 3.05 | J13: 2775 | K13: 24.2 | L13: 3.72 | M13: 4.16 | N13: 1720 | O13: 25 | P13: 3.84 | Q13: 4.14
B14: 6 | C14: =AVERAGE(F14,J14,N14) -> 1956.6667 | D14: =AVERAGE(H14,L14,P14) -> 3.8966667 | E14: =AVERAGE(I14,M14,Q14) -> 4.3133333 | F14: 2220 | G14: 25.5 | H14: 3.68 | I14: 4.39 | J14: 1170 | K14: 26.2 | L14: 4.12 | M14: 4.42 | N14: 2480 | O14: 26.9 | P14: 3.89 | Q14: 4.13
B15: 7 | C15: =AVERAGE(F15,J15,N15) -> 1311.6667 | D15: =AVERAGE(H15,L15,P15) -> 3.7766667 | E15: =AVERAGE(I15,M15,Q15) -> 4.07 | F15: 1055 | G15: 25.5 | H15: 3.64 | I15: 3.86 | J15: 1525 | K15: 23.4 | L15: 3.61 | M15: 4.12 | N15: 1355 | O15: 27.5 | P15: 4.08 | Q15: 4.23
D17: =AVERAGE(H17,L17,P17) -> 3.6787965 | E17: =AVERAGE(I17,M17,Q17) -> 3.998219 | G17: =SUMPRODUCT(F8:F15,G8:G15)/SUM(F8:F15) -> 24.454288 | H17: =SUMPRODUCT(F8:F15,H8:H15)/SUM(F8:F15) -> 3.640769 | I17: =SUMPRODUCT(F8:F15,I8:I15)/SUM(F8:F15) -> 3.9994368 | K17: =SUMPRODUCT(J8:J15,K8:K15)/SUM(J8:J15) -> 24.445569 | L17: =SUMPRODUCT(J8:J15,L8:L15)/SUM(J8:J15) -> 3.7171269 | M17: =SUMPRODUCT(J8:J15,M8:M15)/SUM(J8:J15) -> 4.0253888 | O17: =SUMPRODUCT(N8:N15,O8:O15)/SUM(N8:N15) -> 24.449028 | P17: =SUMPRODUCT(N8:N15,P8:P15)/SUM(N8:N15) -> 3.6784934 | Q17: =SUMPRODUCT(N8:N15,Q8:Q15)/SUM(N8:N15) -> 3.9698313

Sheet TL-Baseline Comparison
C7: 0.1 | F7: 0.2 | I7: 0.3 | L7: 0.4 | O7: 0.5 | U7: 0.1 | X7: 0.2 | AA7: 0.3 | AD7: 0.4 | AG7: 0.5
B8: Clusters | C8: MAE | D8: As Capacity | E8: R-Squared | F8: MAE | G8: As Capacity | H8: R-Squared | I8: MAE | J8: As Capacity | K8: R-Squared | L8: MAE | M8: As Capacity | N8: R-Squared | O8: MAE | P8: As Capacity | Q8: R-Squared | T8: Clusters | U8: MAE | V8: As Capacity | W8: R-Squared | X8: MAE | Y8: As Capacity | Z8: R-Squared | AA8: MAE | AB8: As Capacity | AC8: R-Squared | AD8: MAE | AE8: As Capacity | AF8: R-Squared | AG8: MAE | AH8: As Capacity | AI8: R-Squared
B9: 0 | C9: =AVERAGE('Horns Rev'!D9,Seagreen!D9,Gemini!D9,Hollandse_Noord!D9,Dieppe!D9,'Moray Firth'!D9,Kriegers!D9,'East Anglia One'!D9) -> 33.6875 | D9: =AVERAGE('Horns Rev'!E9,Seagreen!E9,Gemini!E9,Hollandse_Noord!E9,Dieppe!E9,'Moray Firth'!E9,Kriegers!E9,'East Anglia One'!E9) -> 0.043872995 | E9: =AVERAGE('Horns Rev'!F9,Seagreen!F9,Gemini!F9,Hollandse_Noord!F9,Dieppe!F9,'Moray Firth'!F9,Kriegers!F9,'East Anglia One'!F9) -> 0.959125 | F9: =AVERAGE('Horns Rev'!H9,Seagreen!H9,Gemini!H9,Hollandse_Noord!H9,Dieppe!H9,'Moray Firth'!H9,Kriegers!H9,'East Anglia One'!H9) -> 28.854167 | G9: =AVERAGE('Horns Rev'!I9,Seagreen!I9,Gemini!I9,Hollandse_Noord!I9,Dieppe!I9,'Moray Firth'!I9,Kriegers!I9,'East Anglia One'!I9) -> 0.037477947 | H9: =AVERAGE('Horns Rev'!J9,Seagreen!J9,Gemini!J9,Hollandse_Noord!J9,Dieppe!J9,'Moray Firth'!J9,Kriegers!J9,'East Anglia One'!J9) -> 0.96970833 | I9: =AVERAGE('Horns Rev'!L9,Seagreen!L9,Gemini!L9,Hollandse_Noord!L9,Dieppe!L9,'Moray Firth'!L9,Kriegers!L9,'East Anglia One'!L9) -> 26.925 | J9: =AVERAGE('Horns Rev'!M9,Seagreen!M9,Gemini!M9,Hollandse_Noord!M9,Dieppe!M9,'Moray Firth'!M9,Kriegers!M9,'East Anglia One'!M9) -> 0.035064995 | K9: =AVERAGE('Horns Rev'!N9,Seagreen!N9,Gemini!N9,Hollandse_Noord!N9,Dieppe!N9,'Moray Firth'!N9,Kriegers!N9,'East Anglia One'!N9) -> 0.972375 | L9: =AVERAGE('Horns Rev'!P9,Seagreen!P9,Gemini!P9,Hollandse_Noord!P9,Dieppe!P9,'Moray Firth'!P9,Kriegers!P9,'East Anglia One'!P9) -> 27 | M9: =AVERAGE('Horns Rev'!Q9,Seagreen!Q9,Gemini!Q9,Hollandse_Noord!Q9,Dieppe!Q9,'Moray Firth'!Q9,Kriegers!Q9,'East Anglia One'!Q9) -> 0.035155277 | N9: =AVERAGE('Horns Rev'!R9,Seagreen!R9,Gemini!R9,Hollandse_Noord!R9,Dieppe!R9,'Moray Firth'!R9,Kriegers!R9,'East Anglia One'!R9) -> 0.971875 | O9: =AVERAGE('Horns Rev'!T9,Seagreen!T9,Gemini!T9,Hollandse_Noord!T9,Dieppe!T9,'Moray Firth'!T9,Kriegers!T9,'East Anglia One'!T9) -> 26.945833 | P9: =AVERAGE('Horns Rev'!U9,Seagreen!U9,Gemini!U9,Hollandse_Noord!U9,Dieppe!U9,'Moray Firth'!U9,Kriegers!U9,'East Anglia One'!U9) -> 0.035236503 | Q9: =AVERAGE('Horns Rev'!V9,Seagreen!V9,Gemini!V9,Hollandse_Noord!V9,Dieppe!V9,'Moray Firth'!V9,Kriegers!V9,'East Anglia One'!V9) -> 0.97133333 | T9: 0 | U9: =AVERAGE('Horns Rev'!AB9,Seagreen!AB9,Gemini!AB9,Hollandse_Noord!AB9,Dieppe!AA9,'Moray Firth'!AB9,Kriegers!AB9,'East Anglia One'!AB9) -> 40.5 | V9: =AVERAGE('Horns Rev'!AC9,Seagreen!AC9,Gemini!AC9,Hollandse_Noord!AC9,Dieppe!AB9,'Moray Firth'!AC9,Kriegers!AC9,'East Anglia One'!AC9) -> 0.052536291 | W9: =AVERAGE('Horns Rev'!AD9,Seagreen!AD9,Gemini!AD9,Hollandse_Noord!AD9,Dieppe!AC9,'Moray Firth'!AD9,Kriegers!AD9,'East Anglia One'!AD9) -> 0.94454167 | X9: =AVERAGE('Horns Rev'!AF9,Seagreen!AF9,Gemini!AF9,Hollandse_Noord!AF9,Dieppe!AE9,'Moray Firth'!AF9,Kriegers!AF9,'East Anglia One'!AF9) -> 33.716667 | Y9: =AVERAGE('Horns Rev'!AG9,Seagreen!AG9,Gemini!AG9,Hollandse_Noord!AG9,Dieppe!AF9,'Moray Firth'!AG9,Kriegers!AG9,'East Anglia One'!AG9) -> 0.043818205 | Z9: =AVERAGE('Horns Rev'!AH9,Seagreen!AH9,Gemini!AH9,Hollandse_Noord!AH9,Dieppe!AG9,'Moray Firth'!AH9,Kriegers!AH9,'East Anglia One'!AH9) -> 0.96158333 | AA9: =AVERAGE('Horns Rev'!AJ9,Seagreen!AJ9,Gemini!AJ9,Hollandse_Noord!AJ9,Dieppe!AI9,'Moray Firth'!AJ9,Kriegers!AJ9,'East Anglia One'!AJ9) -> 30.795833 | AB9: =AVERAGE('Horns Rev'!AK9,Seagreen!AK9,Gemini!AK9,Hollandse_Noord!AK9,Dieppe!AJ9,'Moray Firth'!AK9,Kriegers!AK9,'East Anglia One'!AK9) -> 0.040092775 | AC9: =AVERAGE('Horns Rev'!AL9,Seagreen!AL9,Gemini!AL9,Hollandse_Noord!AL9,Dieppe!AK9,'Moray Firth'!AL9,Kriegers!AL9,'East Anglia One'!AL9) -> 0.966375 | AD9: =AVERAGE('Horns Rev'!AN9,Seagreen!AN9,Gemini!AN9,Hollandse_Noord!AN9,Dieppe!AM9,'Moray Firth'!AN9,Kriegers!AN9,'East Anglia One'!AN9) -> 30.116667 | AE9: =AVERAGE('Horns Rev'!AO9,Seagreen!AO9,Gemini!AO9,Hollandse_Noord!AO9,Dieppe!AN9,'Moray Firth'!AO9,Kriegers!AO9,'East Anglia One'!AO9) -> 0.039181265 | AF9: =AVERAGE('Horns Rev'!AP9,Seagreen!AP9,Gemini!AP9,Hollandse_Noord!AP9,Dieppe!AO9,'Moray Firth'!AP9,Kriegers!AP9,'East Anglia One'!AP9) -> 0.96754167 | AG9: =AVERAGE('Horns Rev'!AR9,Seagreen!AR9,Gemini!AR9,Hollandse_Noord!AR9,Dieppe!AQ9,'Moray Firth'!AR9,Kriegers!AR9,'East Anglia One'!AR9) -> 29.620833 | AH9: =AVERAGE('Horns Rev'!AS9,Seagreen!AS9,Gemini!AS9,Hollandse_Noord!AS9,Dieppe!AR9,'Moray Firth'!AS9,Kriegers!AS9,'East Anglia One'!AS9) -> 0.038725107 | AI9: =AVERAGE('Horns Rev'!AT9,Seagreen!AT9,Gemini!AT9,Hollandse_Noord!AT9,Dieppe!AS9,'Moray Firth'!AT9,Kriegers!AT9,'East Anglia One'!AT9) -> 0.96754167
B10: 1 | C10: =AVERAGE('Horns Rev'!D10,Seagreen!D10,Gemini!D10,Hollandse_Noord!D10,Dieppe!D10,'Moray Firth'!D10,Kriegers!D10,'East Anglia One'!D10) -> 28.125 | D10: =AVERAGE('Horns Rev'!E10,Seagreen!E10,Gemini!E10,Hollandse_Noord!E10,Dieppe!E10,'Moray Firth'!E10,Kriegers!E10,'East Anglia One'!E10) -> 0.037419011 | E10: =AVERAGE('Horns Rev'!F10,Seagreen!F10,Gemini!F10,Hollandse_Noord!F10,Dieppe!F10,'Moray Firth'!F10,Kriegers!F10,'East Anglia One'!F10) -> 0.95291667 | F10: =AVERAGE('Horns Rev'!H10,Seagreen!H10,Gemini!H10,Hollandse_Noord!H10,Dieppe!H10,'Moray Firth'!H10,Kriegers!H10,'East Anglia One'!H10) -> 24.9 | G10: =AVERAGE('Horns Rev'!I10,Seagreen!I10,Gemini!I10,Hollandse_Noord!I10,Dieppe!I10,'Moray Firth'!I10,Kriegers!I10,'East Anglia One'!I10) -> 0.03301889 | H10: =AVERAGE('Horns Rev'!J10,Seagreen!J10,Gemini!J10,Hollandse_Noord!J10,Dieppe!J10,'Moray Firth'!J10,Kriegers!J10,'East Anglia One'!J10) -> 0.96008333 | I10: =AVERAGE('Horns Rev'!L10,Seagreen!L10,Gemini!L10,Hollandse_Noord!L10,Dieppe!L10,'Moray Firth'!L10,Kriegers!L10,'East Anglia One'!L10) -> 23.916667 | J10: =AVERAGE('Horns Rev'!M10,Seagreen!M10,Gemini!M10,Hollandse_Noord!M10,Dieppe!M10,'Moray Firth'!M10,Kriegers!M10,'East Anglia One'!M10) -> 0.031866803 | K10: =AVERAGE('Horns Rev'!N10,Seagreen!N10,Gemini!N10,Hollandse_Noord!N10,Dieppe!N10,'Moray Firth'!N10,Kriegers!N10,'East Anglia One'!N10) -> 0.96204167 | L10: =AVERAGE('Horns Rev'!P10,Seagreen!P10,Gemini!P10,Hollandse_Noord!P10,Dieppe!P10,'Moray Firth'!P10,Kriegers!P10,'East Anglia One'!P10) -> 23.879167 | M10: =AVERAGE('Horns Rev'!Q10,Seagreen!Q10,Gemini!Q10,Hollandse_Noord!Q10,Dieppe!Q10,'Moray Firth'!Q10,Kriegers!Q10,'East Anglia One'!Q10) -> 0.03170033 | N10: =AVERAGE('Horns Rev'!R10,Seagreen!R10,Gemini!R10,Hollandse_Noord!R10,Dieppe!R10,'Moray Firth'!R10,Kriegers!R10,'East Anglia One'!R10) -> 0.963 | O10: =AVERAGE('Horns Rev'!T10,Seagreen!T10,Gemini!T10,Hollandse_Noord!T10,Dieppe!T10,'Moray Firth'!T10,Kriegers!T10,'East Anglia One'!T10) -> 23.570833 | P10: =AVERAGE('Horns Rev'!U10,Seagreen!U10,Gemini!U10,Hollandse_Noord!U10,Dieppe!U10,'Moray Firth'!U10,Kriegers!U10,'East Anglia One'!U10) -> 0.031376434 | Q10: =AVERAGE('Horns Rev'!V10,Seagreen!V10,Gemini!V10,Hollandse_Noord!V10,Dieppe!V10,'Moray Firth'!V10,Kriegers!V10,'East Anglia One'!V10) -> 0.96441667 | T10: 1 | U10: =AVERAGE('Horns Rev'!AB10,Seagreen!AB10,Gemini!AB10,Hollandse_Noord!AB10,Dieppe!AA10,'Moray Firth'!AB10,Kriegers!AB10,'East Anglia One'!AB10) -> 33.833333 | V10: =AVERAGE('Horns Rev'!AC10,Seagreen!AC10,Gemini!AC10,Hollandse_Noord!AC10,Dieppe!AB10,'Moray Firth'!AC10,Kriegers!AC10,'East Anglia One'!AC10) -> 0.044931154 | W10: =AVERAGE('Horns Rev'!AD10,Seagreen!AD10,Gemini!AD10,Hollandse_Noord!AD10,Dieppe!AC10,'Moray Firth'!AD10,Kriegers!AD10,'East Anglia One'!AD10) -> 0.93441667 | X10: =AVERAGE('Horns Rev'!AF10,Seagreen!AF10,Gemini!AF10,Hollandse_Noord!AF10,Dieppe!AE10,'Moray Firth'!AF10,Kriegers!AF10,'East Anglia One'!AF10) -> 28.683333 | Y10: =AVERAGE('Horns Rev'!AG10,Seagreen!AG10,Gemini!AG10,Hollandse_Noord!AG10,Dieppe!AF10,'Moray Firth'!AG10,Kriegers!AG10,'East Anglia One'!AG10) -> 0.03794249 | Z10: =AVERAGE('Horns Rev'!AH10,Seagreen!AH10,Gemini!AH10,Hollandse_Noord!AH10,Dieppe!AG10,'Moray Firth'!AH10,Kriegers!AH10,'East Anglia One'!AH10) -> 0.95125 | AA10: =AVERAGE('Horns Rev'!AJ10,Seagreen!AJ10,Gemini!AJ10,Hollandse_Noord!AJ10,Dieppe!AI10,'Moray Firth'!AJ10,Kriegers!AJ10,'East Anglia One'!AJ10) -> 26.541667 | AB10: =AVERAGE('Horns Rev'!AK10,Seagreen!AK10,Gemini!AK10,Hollandse_Noord!AK10,Dieppe!AJ10,'Moray Firth'!AK10,Kriegers!AK10,'East Anglia One'!AK10) -> 0.035249958 | AC10: =AVERAGE('Horns Rev'!AL10,Seagreen!AL10,Gemini!AL10,Hollandse_Noord!AL10,Dieppe!AK10,'Moray Firth'!AL10,Kriegers!AL10,'East Anglia One'!AL10) -> 0.95625 | AD10: =AVERAGE('Horns Rev'!AN10,Seagreen!AN10,Gemini!AN10,Hollandse_Noord!AN10,Dieppe!AM10,'Moray Firth'!AN10,Kriegers!AN10,'East Anglia One'!AN10) -> 26.166667 | AE10: =AVERAGE('Horns Rev'!AO10,Seagreen!AO10,Gemini!AO10,Hollandse_Noord!AO10,Dieppe!AN10,'Moray Firth'!AO10,Kriegers!AO10,'East Anglia One'!AO10) -> 0.034637741 | AF10: =AVERAGE('Horns Rev'!AP10,Seagreen!AP10,Gemini!AP10,Hollandse_Noord!AP10,Dieppe!AO10,'Moray Firth'!AP10,Kriegers!AP10,'East Anglia One'!AP10) -> 0.95895833 | AG10: =AVERAGE('Horns Rev'!AR10,Seagreen!AR10,Gemini!AR10,Hollandse_Noord!AR10,Dieppe!AQ10,'Moray Firth'!AR10,Kriegers!AR10,'East Anglia One'!AR10) -> 25.470833 | AH10: =AVERAGE('Horns Rev'!AS10,Seagreen!AS10,Gemini!AS10,Hollandse_Noord!AS10,Dieppe!AR10,'Moray Firth'!AS10,Kriegers!AS10,'East Anglia One'!AS10) -> 0.033813524 | AI10: =AVERAGE('Horns Rev'!AT10,Seagreen!AT10,Gemini!AT10,Hollandse_Noord!AT10,Dieppe!AS10,'Moray Firth'!AT10,Kriegers!AT10,'East Anglia One'!AT10) -> 0.96125
B11: 2 | C11: =AVERAGE('Horns Rev'!D11,Seagreen!D11,Gemini!D11,Hollandse_Noord!D11,Dieppe!D11,'Moray Firth'!D11,Kriegers!D11,'East Anglia One'!D11) -> 29.85 | D11: =AVERAGE('Horns Rev'!E11,Seagreen!E11,Gemini!E11,Hollandse_Noord!E11,Dieppe!E11,'Moray Firth'!E11,Kriegers!E11,'East Anglia One'!E11) -> 0.039216647 | E11: =AVERAGE('Horns Rev'!F11,Seagreen!F11,Gemini!F11,Hollandse_Noord!F11,Dieppe!F11,'Moray Firth'!F11,Kriegers!F11,'East Anglia One'!F11) -> 0.84604167 | F11: =AVERAGE('Horns Rev'!H11,Seagreen!H11,Gemini!H11,Hollandse_Noord!H11,Dieppe!H11,'Moray Firth'!H11,Kriegers!H11,'East Anglia One'!H11) -> 24.983333 | G11: =AVERAGE('Horns Rev'!I11,Seagreen!I11,Gemini!I11,Hollandse_Noord!I11,Dieppe!I11,'Moray Firth'!I11,Kriegers!I11,'East Anglia One'!I11) -> 0.032458326 | H11: =AVERAGE('Horns Rev'!J11,Seagreen!J11,Gemini!J11,Hollandse_Noord!J11,Dieppe!J11,'Moray Firth'!J11,Kriegers!J11,'East Anglia One'!J11) -> 0.89395833 | I11: =AVERAGE('Horns Rev'!L11,Seagreen!L11,Gemini!L11,Hollandse_Noord!L11,Dieppe!L11,'Moray Firth'!L11,Kriegers!L11,'East Anglia One'!L11) -> 23.2 | J11: =AVERAGE('Horns Rev'!M11,Seagreen!M11,Gemini!M11,Hollandse_Noord!M11,Dieppe!M11,'Moray Firth'!M11,Kriegers!M11,'East Anglia One'!M11) -> 0.030087304 | K11: =AVERAGE('Horns Rev'!N11,Seagreen!N11,Gemini!N11,Hollandse_Noord!N11,Dieppe!N11,'Moray Firth'!N11,Kriegers!N11,'East Anglia One'!N11) -> 0.90508333 | L11: =AVERAGE('Horns Rev'!P11,Seagreen!P11,Gemini!P11,Hollandse_Noord!P11,Dieppe!P11,'Moray Firth'!P11,Kriegers!P11,'East Anglia One'!P11) -> 22.679167 | M11: =AVERAGE('Horns Rev'!Q11,Seagreen!Q11,Gemini!Q11,Hollandse_Noord!Q11,Dieppe!Q11,'Moray Firth'!Q11,Kriegers!Q11,'East Anglia One'!Q11) -> 0.029163041 | N11: =AVERAGE('Horns Rev'!R11,Seagreen!R11,Gemini!R11,Hollandse_Noord!R11,Dieppe!R11,'Moray Firth'!R11,Kriegers!R11,'East Anglia One'!R11) -> 0.91366667 | O11: =AVERAGE('Horns Rev'!T11,Seagreen!T11,Gemini!T11,Hollandse_Noord!T11,Dieppe!T11,'Moray Firth'!T11,Kriegers!T11,'East Anglia One'!T11) -> 22.895833 | P11: =AVERAGE('Horns Rev'!U11,Seagreen!U11,Gemini!U11,Hollandse_Noord!U11,Dieppe!U11,'Moray Firth'!U11,Kriegers!U11,'East Anglia One'!U11) -> 0.029343994 | Q11: =AVERAGE('Horns Rev'!V11,Seagreen!V11,Gemini!V11,Hollandse_Noord!V11,Dieppe!V11,'Moray Firth'!V11,Kriegers!V11,'East Anglia One'!V11) -> 0.91329167 | T11: 2 | U11: =AVERAGE('Horns Rev'!AB11,Seagreen!AB11,Gemini!AB11,Hollandse_Noord!AB11,Dieppe!AA11,'Moray Firth'!AB11,Kriegers!AB11,'East Anglia One'!AB11) -> 35.716667 | V11: =AVERAGE('Horns Rev'!AC11,Seagreen!AC11,Gemini!AC11,Hollandse_Noord!AC11,Dieppe!AB11,'Moray Firth'!AC11,Kriegers!AC11,'East Anglia One'!AC11) -> 0.046450283 | W11: =AVERAGE('Horns Rev'!AD11,Seagreen!AD11,Gemini!AD11,Hollandse_Noord!AD11,Dieppe!AC11,'Moray Firth'!AD11,Kriegers!AD11,'East Anglia One'!AD11) -> 0.806875 | X11: =AVERAGE('Horns Rev'!AF11,Seagreen!AF11,Gemini!AF11,Hollandse_Noord!AF11,Dieppe!AE11,'Moray Firth'!AF11,Kriegers!AF11,'East Anglia One'!AF11) -> 28.4875 | Y11: =AVERAGE('Horns Rev'!AG11,Seagreen!AG11,Gemini!AG11,Hollandse_Noord!AG11,Dieppe!AF11,'Moray Firth'!AG11,Kriegers!AG11,'East Anglia One'!AG11) -> 0.036973593 | Z11: =AVERAGE('Horns Rev'!AH11,Seagreen!AH11,Gemini!AH11,Hollandse_Noord!AH11,Dieppe!AG11,'Moray Firth'!AH11,Kriegers!AH11,'East Anglia One'!AH11) -> 0.87945833 | AA11: =AVERAGE('Horns Rev'!AJ11,Seagreen!AJ11,Gemini!AJ11,Hollandse_Noord!AJ11,Dieppe!AI11,'Moray Firth'!AJ11,Kriegers!AJ11,'East Anglia One'!AJ11) -> 26.195833 | AB11: =AVERAGE('Horns Rev'!AK11,Seagreen!AK11,Gemini!AK11,Hollandse_Noord!AK11,Dieppe!AJ11,'Moray Firth'!AK11,Kriegers!AK11,'East Anglia One'!AK11) -> 0.033987945 | AC11: =AVERAGE('Horns Rev'!AL11,Seagreen!AL11,Gemini!AL11,Hollandse_Noord!AL11,Dieppe!AK11,'Moray Firth'!AL11,Kriegers!AL11,'East Anglia One'!AL11) -> 0.88945833 | AD11: =AVERAGE('Horns Rev'!AN11,Seagreen!AN11,Gemini!AN11,Hollandse_Noord!AN11,Dieppe!AM11,'Moray Firth'!AN11,Kriegers!AN11,'East Anglia One'!AN11) -> 24.904167 | AE11: =AVERAGE('Horns Rev'!AO11,Seagreen!AO11,Gemini!AO11,Hollandse_Noord!AO11,Dieppe!AN11,'Moray Firth'!AO11,Kriegers!AO11,'East Anglia One'!AO11) -> 0.031994586 | AF11: =AVERAGE('Horns Rev'!AP11,Seagreen!AP11,Gemini!AP11,Hollandse_Noord!AP11,Dieppe!AO11,'Moray Firth'!AP11,Kriegers!AP11,'East Anglia One'!AP11) -> 0.90379167 | AG11: =AVERAGE('Horns Rev'!AR11,Seagreen!AR11,Gemini!AR11,Hollandse_Noord!AR11,Dieppe!AQ11,'Moray Firth'!AR11,Kriegers!AR11,'East Anglia One'!AR11) -> 24.483333 | AH11: =AVERAGE('Horns Rev'!AS11,Seagreen!AS11,Gemini!AS11,Hollandse_Noord!AS11,Dieppe!AR11,'Moray Firth'!AS11,Kriegers!AS11,'East Anglia One'!AS11) -> 0.031531179 | AI11: =AVERAGE('Horns Rev'!AT11,Seagreen!AT11,Gemini!AT11,Hollandse_Noord!AT11,Dieppe!AS11,'Moray Firth'!AT11,Kriegers!AT11,'East Anglia One'!AT11) -> 0.906875
B12: 3 | C12: =AVERAGE('Horns Rev'!D12,Seagreen!D12,Gemini!D12,Hollandse_Noord!D12,Dieppe!D12,'Moray Firth'!D12,Kriegers!D12,'East Anglia One'!D12) -> 34.008333 | D12: =AVERAGE('Horns Rev'!E12,Seagreen!E12,Gemini!E12,Hollandse_Noord!E12,Dieppe!E12,'Moray Firth'!E12,Kriegers!E12,'East Anglia One'!E12) -> 0.045351031 | E12: =AVERAGE('Horns Rev'!F12,Seagreen!F12,Gemini!F12,Hollandse_Noord!F12,Dieppe!F12,'Moray Firth'!F12,Kriegers!F12,'East Anglia One'!F12) -> 0.96325 | F12: =AVERAGE('Horns Rev'!H12,Seagreen!H12,Gemini!H12,Hollandse_Noord!H12,Dieppe!H12,'Moray Firth'!H12,Kriegers!H12,'East Anglia One'!H12) -> 27.091667 | G12: =AVERAGE('Horns Rev'!I12,Seagreen!I12,Gemini!I12,Hollandse_Noord!I12,Dieppe!I12,'Moray Firth'!I12,Kriegers!I12,'East Anglia One'!I12) -> 0.036529608 | H12: =AVERAGE('Horns Rev'!J12,Seagreen!J12,Gemini!J12,Hollandse_Noord!J12,Dieppe!J12,'Moray Firth'!J12,Kriegers!J12,'East Anglia One'!J12) -> 0.9735 | I12: =AVERAGE('Horns Rev'!L12,Seagreen!L12,Gemini!L12,Hollandse_Noord!L12,Dieppe!L12,'Moray Firth'!L12,Kriegers!L12,'East Anglia One'!L12) -> 24.716667 | J12: =AVERAGE('Horns Rev'!M12,Seagreen!M12,Gemini!M12,Hollandse_Noord!M12,Dieppe!M12,'Moray Firth'!M12,Kriegers!M12,'East Anglia One'!M12) -> 0.032899687 | K12: =AVERAGE('Horns Rev'!N12,Seagreen!N12,Gemini!N12,Hollandse_Noord!N12,Dieppe!N12,'Moray Firth'!N12,Kriegers!N12,'East Anglia One'!N12) -> 0.97729167 | L12: =AVERAGE('Horns Rev'!P12,Seagreen!P12,Gemini!P12,Hollandse_Noord!P12,Dieppe!P12,'Moray Firth'!P12,Kriegers!P12,'East Anglia One'!P12) -> 24.208333 | M12: =AVERAGE('Horns Rev'!Q12,Seagreen!Q12,Gemini!Q12,Hollandse_Noord!Q12,Dieppe!Q12,'Moray Firth'!Q12,Kriegers!Q12,'East Anglia One'!Q12) -> 0.032325947 | N12: =AVERAGE('Horns Rev'!R12,Seagreen!R12,Gemini!R12,Hollandse_Noord!R12,Dieppe!R12,'Moray Firth'!R12,Kriegers!R12,'East Anglia One'!R12) -> 0.97791667 | O12: =AVERAGE('Horns Rev'!T12,Seagreen!T12,Gemini!T12,Hollandse_Noord!T12,Dieppe!T12,'Moray Firth'!T12,Kriegers!T12,'East Anglia One'!T12) -> 24.383333 | P12: =AVERAGE('Horns Rev'!U12,Seagreen!U12,Gemini!U12,Hollandse_Noord!U12,Dieppe!U12,'Moray Firth'!U12,Kriegers!U12,'East Anglia One'!U12) -> 0.032291746 | Q12: =AVERAGE('Horns Rev'!V12,Seagreen!V12,Gemini!V12,Hollandse_Noord!V12,Dieppe!V12,'Moray Firth'!V12,Kriegers!V12,'East Anglia One'!V12) -> 0.97745833 | T12: 3 | U12: =AVERAGE('Horns Rev'!AB12,Seagreen!AB12,Gemini!AB12,Hollandse_Noord!AB12,Dieppe!AA12,'Moray Firth'!AB12,Kriegers!AB12,'East Anglia One'!AB12) -> 41.095833 | V12: =AVERAGE('Horns Rev'!AC12,Seagreen!AC12,Gemini!AC12,Hollandse_Noord!AC12,Dieppe!AB12,'Moray Firth'!AC12,Kriegers!AC12,'East Anglia One'!AC12) -> 0.055360524 | W12: =AVERAGE('Horns Rev'!AD12,Seagreen!AD12,Gemini!AD12,Hollandse_Noord!AD12,Dieppe!AC12,'Moray Firth'!AD12,Kriegers!AD12,'East Anglia One'!AD12) -> 0.94841667 | X12: =AVERAGE('Horns Rev'!AF12,Seagreen!AF12,Gemini!AF12,Hollandse_Noord!AF12,Dieppe!AE12,'Moray Firth'!AF12,Kriegers!AF12,'East Anglia One'!AF12) -> 32.516667 | Y12: =AVERAGE('Horns Rev'!AG12,Seagreen!AG12,Gemini!AG12,Hollandse_Noord!AG12,Dieppe!AF12,'Moray Firth'!AG12,Kriegers!AG12,'East Anglia One'!AG12) -> 0.044001333 | Z12: =AVERAGE('Horns Rev'!AH12,Seagreen!AH12,Gemini!AH12,Hollandse_Noord!AH12,Dieppe!AG12,'Moray Firth'!AH12,Kriegers!AH12,'East Anglia One'!AH12) -> 0.96491667 | AA12: =AVERAGE('Horns Rev'!AJ12,Seagreen!AJ12,Gemini!AJ12,Hollandse_Noord!AJ12,Dieppe!AI12,'Moray Firth'!AJ12,Kriegers!AJ12,'East Anglia One'!AJ12) -> 28.175 | AB12: =AVERAGE('Horns Rev'!AK12,Seagreen!AK12,Gemini!AK12,Hollandse_Noord!AK12,Dieppe!AJ12,'Moray Firth'!AK12,Kriegers!AK12,'East Anglia One'!AK12) -> 0.037634558 | AC12: =AVERAGE('Horns Rev'!AL12,Seagreen!AL12,Gemini!AL12,Hollandse_Noord!AL12,Dieppe!AK12,'Moray Firth'!AL12,Kriegers!AL12,'East Anglia One'!AL12) -> 0.973 | AD12: =AVERAGE('Horns Rev'!AN12,Seagreen!AN12,Gemini!AN12,Hollandse_Noord!AN12,Dieppe!AM12,'Moray Firth'!AN12,Kriegers!AN12,'East Anglia One'!AN12) -> 27.25 | AE12: =AVERAGE('Horns Rev'!AO12,Seagreen!AO12,Gemini!AO12,Hollandse_Noord!AO12,Dieppe!AN12,'Moray Firth'!AO12,Kriegers!AO12,'East Anglia One'!AO12) -> 0.03635087 | AF12: =AVERAGE('Horns Rev'!AP12,Seagreen!AP12,Gemini!AP12,Hollandse_Noord!AP12,Dieppe!AO12,'Moray Firth'!AP12,Kriegers!AP12,'East Anglia One'!AP12) -> 0.9745 | AG12: =AVERAGE('Horns Rev'!AR12,Seagreen!AR12,Gemini!AR12,Hollandse_Noord!AR12,Dieppe!AQ12,'Moray Firth'!AR12,Kriegers!AR12,'East Anglia One'!AR12) -> 27.891667 | AH12: =AVERAGE('Horns Rev'!AS12,Seagreen!AS12,Gemini!AS12,Hollandse_Noord!AS12,Dieppe!AR12,'Moray Firth'!AS12,Kriegers!AS12,'East Anglia One'!AS12) -> 0.037208841 | AI12: =AVERAGE('Horns Rev'!AT12,Seagreen!AT12,Gemini!AT12,Hollandse_Noord!AT12,Dieppe!AS12,'Moray Firth'!AT12,Kriegers!AT12,'East Anglia One'!AT12) -> 0.974
B13: 4 | C13: =AVERAGE('Horns Rev'!D13,Seagreen!D13,Gemini!D13,Hollandse_Noord!D13,Dieppe!D13,'Moray Firth'!D13,Kriegers!D13,'East Anglia One'!D13) -> 37.058333 | D13: =AVERAGE('Horns Rev'!E13,Seagreen!E13,Gemini!E13,Hollandse_Noord!E13,Dieppe!E13,'Moray Firth'!E13,Kriegers!E13,'East Anglia One'!E13) -> 0.050667609 | E13: =AVERAGE('Horns Rev'!F13,Seagreen!F13,Gemini!F13,Hollandse_Noord!F13,Dieppe!F13,'Moray Firth'!F13,Kriegers!F13,'East Anglia One'!F13) -> 0.94441667 | F13: =AVERAGE('Horns Rev'!H13,Seagreen!H13,Gemini!H13,Hollandse_Noord!H13,Dieppe!H13,'Moray Firth'!H13,Kriegers!H13,'East Anglia One'!H13) -> 28.85 | G13: =AVERAGE('Horns Rev'!I13,Seagreen!I13,Gemini!I13,Hollandse_Noord!I13,Dieppe!I13,'Moray Firth'!I13,Kriegers!I13,'East Anglia One'!I13) -> 0.038682259 | H13: =AVERAGE('Horns Rev'!J13,Seagreen!J13,Gemini!J13,Hollandse_Noord!J13,Dieppe!J13,'Moray Firth'!J13,Kriegers!J13,'East Anglia One'!J13) -> 0.96758333 | I13: =AVERAGE('Horns Rev'!L13,Seagreen!L13,Gemini!L13,Hollandse_Noord!L13,Dieppe!L13,'Moray Firth'!L13,Kriegers!L13,'East Anglia One'!L13) -> 26.245833 | J13: =AVERAGE('Horns Rev'!M13,Seagreen!M13,Gemini!M13,Hollandse_Noord!M13,Dieppe!M13,'Moray Firth'!M13,Kriegers!M13,'East Anglia One'!M13) -> 0.035165692 | K13: =AVERAGE('Horns Rev'!N13,Seagreen!N13,Gemini!N13,Hollandse_Noord!N13,Dieppe!N13,'Moray Firth'!N13,Kriegers!N13,'East Anglia One'!N13) -> 0.97279167 | L13: =AVERAGE('Horns Rev'!P13,Seagreen!P13,Gemini!P13,Hollandse_Noord!P13,Dieppe!P13,'Moray Firth'!P13,Kriegers!P13,'East Anglia One'!P13) -> 25.525 | M13: =AVERAGE('Horns Rev'!Q13,Seagreen!Q13,Gemini!Q13,Hollandse_Noord!Q13,Dieppe!Q13,'Moray Firth'!Q13,Kriegers!Q13,'East Anglia One'!Q13) -> 0.034109615 | N13: =AVERAGE('Horns Rev'!R13,Seagreen!R13,Gemini!R13,Hollandse_Noord!R13,Dieppe!R13,'Moray Firth'!R13,Kriegers!R13,'East Anglia One'!R13) -> 0.97408333 | O13: =AVERAGE('Horns Rev'!T13,Seagreen!T13,Gemini!T13,Hollandse_Noord!T13,Dieppe!T13,'Moray Firth'!T13,Kriegers!T13,'East Anglia One'!T13) -> 25.658333 | P13: =AVERAGE('Horns Rev'!U13,Seagreen!U13,Gemini!U13,Hollandse_Noord!U13,Dieppe!U13,'Moray Firth'!U13,Kriegers!U13,'East Anglia One'!U13) -> 0.03423643 | Q13: =AVERAGE('Horns Rev'!V13,Seagreen!V13,Gemini!V13,Hollandse_Noord!V13,Dieppe!V13,'Moray Firth'!V13,Kriegers!V13,'East Anglia One'!V13) -> 0.97358333 | T13: 4 | U13: =AVERAGE('Horns Rev'!AB13,Seagreen!AB13,Gemini!AB13,Hollandse_Noord!AB13,Dieppe!AA13,'Moray Firth'!AB13,Kriegers!AB13,'East Anglia One'!AB13) -> 44.425 | V13: =AVERAGE('Horns Rev'!AC13,Seagreen!AC13,Gemini!AC13,Hollandse_Noord!AC13,Dieppe!AB13,'Moray Firth'!AC13,Kriegers!AC13,'East Anglia One'!AC13) -> 0.060349408 | W13: =AVERAGE('Horns Rev'!AD13,Seagreen!AD13,Gemini!AD13,Hollandse_Noord!AD13,Dieppe!AC13,'Moray Firth'!AD13,Kriegers!AD13,'East Anglia One'!AD13) -> 0.9305 | X13: =AVERAGE('Horns Rev'!AF13,Seagreen!AF13,Gemini!AF13,Hollandse_Noord!AF13,Dieppe!AE13,'Moray Firth'!AF13,Kriegers!AF13,'East Anglia One'!AF13) -> 34.4625 | Y13: =AVERAGE('Horns Rev'!AG13,Seagreen!AG13,Gemini!AG13,Hollandse_Noord!AG13,Dieppe!AF13,'Moray Firth'!AG13,Kriegers!AG13,'East Anglia One'!AG13) -> 0.046260123 | Z13: =AVERAGE('Horns Rev'!AH13,Seagreen!AH13,Gemini!AH13,Hollandse_Noord!AH13,Dieppe!AG13,'Moray Firth'!AH13,Kriegers!AH13,'East Anglia One'!AH13) -> 0.95608333 | AA13: =AVERAGE('Horns Rev'!AJ13,Seagreen!AJ13,Gemini!AJ13,Hollandse_Noord!AJ13,Dieppe!AI13,'Moray Firth'!AJ13,Kriegers!AJ13,'East Anglia One'!AJ13) -> 30.258333 | AB13: =AVERAGE('Horns Rev'!AK13,Seagreen!AK13,Gemini!AK13,Hollandse_Noord!AK13,Dieppe!AJ13,'Moray Firth'!AK13,Kriegers!AK13,'East Anglia One'!AK13) -> 0.040603796 | AC13: =AVERAGE('Horns Rev'!AL13,Seagreen!AL13,Gemini!AL13,Hollandse_Noord!AL13,Dieppe!AK13,'Moray Firth'!AL13,Kriegers!AL13,'East Anglia One'!AL13) -> 0.965875 | AD13: =AVERAGE('Horns Rev'!AN13,Seagreen!AN13,Gemini!AN13,Hollandse_Noord!AN13,Dieppe!AM13,'Moray Firth'!AN13,Kriegers!AN13,'East Anglia One'!AN13) -> 28.816667 | AE13: =AVERAGE('Horns Rev'!AO13,Seagreen!AO13,Gemini!AO13,Hollandse_Noord!AO13,Dieppe!AN13,'Moray Firth'!AO13,Kriegers!AO13,'East Anglia One'!AO13) -> 0.038508927 | AF13: =AVERAGE('Horns Rev'!AP13,Seagreen!AP13,Gemini!AP13,Hollandse_Noord!AP13,Dieppe!AO13,'Moray Firth'!AP13,Kriegers!AP13,'East Anglia One'!AP13) -> 0.96870833 | AG13: =AVERAGE('Horns Rev'!AR13,Seagreen!AR13,Gemini!AR13,Hollandse_Noord!AR13,Dieppe!AQ13,'Moray Firth'!AR13,Kriegers!AR13,'East Anglia One'!AR13) -> 29.075 | AH13: =AVERAGE('Horns Rev'!AS13,Seagreen!AS13,Gemini!AS13,Hollandse_Noord!AS13,Dieppe!AR13,'Moray Firth'!AS13,Kriegers!AS13,'East Anglia One'!AS13) -> 0.038827358 | AI13: =AVERAGE('Horns Rev'!AT13,Seagreen!AT13,Gemini!AT13,Hollandse_Noord!AT13,Dieppe!AS13,'Moray Firth'!AT13,Kriegers!AT13,'East Anglia One'!AT13) -> 0.967875
B14: 5 | C14: =AVERAGE('Horns Rev'!D14,Seagreen!D14,Gemini!D14,Hollandse_Noord!D14,Dieppe!D14,'Moray Firth'!D14,Kriegers!D14,'East Anglia One'!D14) -> 33.154167 | D14: =AVERAGE('Horns Rev'!E14,Seagreen!E14,Gemini!E14,Hollandse_Noord!E14,Dieppe!E14,'Moray Firth'!E14,Kriegers!E14,'East Anglia One'!E14) -> 0.044557996 | E14: =AVERAGE('Horns Rev'!F14,Seagreen!F14,Gemini!F14,Hollandse_Noord!F14,Dieppe!F14,'Moray Firth'!F14,Kriegers!F14,'East Anglia One'!F14) -> 0.93558333 | F14: =AVERAGE('Horns Rev'!H14,Seagreen!H14,Gemini!H14,Hollandse_Noord!H14,Dieppe!H14,'Moray Firth'!H14,Kriegers!H14,'East Anglia One'!H14) -> 26.525 | G14: =AVERAGE('Horns Rev'!I14,Seagreen!I14,Gemini!I14,Hollandse_Noord!I14,Dieppe!I14,'Moray Firth'!I14,Kriegers!I14,'East Anglia One'!I14) -> 0.035608217 | H14: =AVERAGE('Horns Rev'!J14,Seagreen!J14,Gemini!J14,Hollandse_Noord!J14,Dieppe!J14,'Moray Firth'!J14,Kriegers!J14,'East Anglia One'!J14) -> 0.95466667 | I14: =AVERAGE('Horns Rev'!L14,Seagreen!L14,Gemini!L14,Hollandse_Noord!L14,Dieppe!L14,'Moray Firth'!L14,Kriegers!L14,'East Anglia One'!L14) -> 24.15 | J14: =AVERAGE('Horns Rev'!M14,Seagreen!M14,Gemini!M14,Hollandse_Noord!M14,Dieppe!M14,'Moray Firth'!M14,Kriegers!M14,'East Anglia One'!M14) -> 0.032495905 | K14: =AVERAGE('Horns Rev'!N14,Seagreen!N14,Gemini!N14,Hollandse_Noord!N14,Dieppe!N14,'Moray Firth'!N14,Kriegers!N14,'East Anglia One'!N14) -> 0.96133333 | L14: =AVERAGE('Horns Rev'!P14,Seagreen!P14,Gemini!P14,Hollandse_Noord!P14,Dieppe!P14,'Moray Firth'!P14,Kriegers!P14,'East Anglia One'!P14) -> 22.983333 | M14: =AVERAGE('Horns Rev'!Q14,Seagreen!Q14,Gemini!Q14,Hollandse_Noord!Q14,Dieppe!Q14,'Moray Firth'!Q14,Kriegers!Q14,'East Anglia One'!Q14) -> 0.031066452 | N14: =AVERAGE('Horns Rev'!R14,Seagreen!R14,Gemini!R14,Hollandse_Noord!R14,Dieppe!R14,'Moray Firth'!R14,Kriegers!R14,'East Anglia One'!R14) -> 0.96504167 | O14: =AVERAGE('Horns Rev'!T14,Seagreen!T14,Gemini!T14,Hollandse_Noord!T14,Dieppe!T14,'Moray Firth'!T14,Kriegers!T14,'East Anglia One'!T14) -> 22.9125 | P14: =AVERAGE('Horns Rev'!U14,Seagreen!U14,Gemini!U14,Hollandse_Noord!U14,Dieppe!U14,'Moray Firth'!U14,Kriegers!U14,'East Anglia One'!U14) -> 0.030844717 | Q14: =AVERAGE('Horns Rev'!V14,Seagreen!V14,Gemini!V14,Hollandse_Noord!V14,Dieppe!V14,'Moray Firth'!V14,Kriegers!V14,'East Anglia One'!V14) -> 0.96516667 | T14: 5 | U14: =AVERAGE('Horns Rev'!AB14,Seagreen!AB14,Gemini!AB14,Hollandse_Noord!AB14,Dieppe!AA14,'Moray Firth'!AB14,Kriegers!AB14,'East Anglia One'!AB14) -> 42.454167 | V14: =AVERAGE('Horns Rev'!AC14,Seagreen!AC14,Gemini!AC14,Hollandse_Noord!AC14,Dieppe!AB14,'Moray Firth'!AC14,Kriegers!AC14,'East Anglia One'!AC14) -> 0.0561686 | W14: =AVERAGE('Horns Rev'!AD14,Seagreen!AD14,Gemini!AD14,Hollandse_Noord!AD14,Dieppe!AC14,'Moray Firth'!AD14,Kriegers!AD14,'East Anglia One'!AD14) -> 0.90295833 | X14: =AVERAGE('Horns Rev'!AF14,Seagreen!AF14,Gemini!AF14,Hollandse_Noord!AF14,Dieppe!AE14,'Moray Firth'!AF14,Kriegers!AF14,'East Anglia One'!AF14) -> 31.970833 | Y14: =AVERAGE('Horns Rev'!AG14,Seagreen!AG14,Gemini!AG14,Hollandse_Noord!AG14,Dieppe!AF14,'Moray Firth'!AG14,Kriegers!AG14,'East Anglia One'!AG14) -> 0.042335661 | Z14: =AVERAGE('Horns Rev'!AH14,Seagreen!AH14,Gemini!AH14,Hollandse_Noord!AH14,Dieppe!AG14,'Moray Firth'!AH14,Kriegers!AH14,'East Anglia One'!AH14) -> 0.943125 | AA14: =AVERAGE('Horns Rev'!AJ14,Seagreen!AJ14,Gemini!AJ14,Hollandse_Noord!AJ14,Dieppe!AI14,'Moray Firth'!AJ14,Kriegers!AJ14,'East Anglia One'!AJ14) -> 27.791667 | AB14: =AVERAGE('Horns Rev'!AK14,Seagreen!AK14,Gemini!AK14,Hollandse_Noord!AK14,Dieppe!AJ14,'Moray Firth'!AK14,Kriegers!AK14,'East Anglia One'!AK14) -> 0.037079623 | AC14: =AVERAGE('Horns Rev'!AL14,Seagreen!AL14,Gemini!AL14,Hollandse_Noord!AL14,Dieppe!AK14,'Moray Firth'!AL14,Kriegers!AL14,'East Anglia One'!AL14) -> 0.954625 | AD14: =AVERAGE('Horns Rev'!AN14,Seagreen!AN14,Gemini!AN14,Hollandse_Noord!AN14,Dieppe!AM14,'Moray Firth'!AN14,Kriegers!AN14,'East Anglia One'!AN14) -> 26.1875 | AE14: =AVERAGE('Horns Rev'!AO14,Seagreen!AO14,Gemini!AO14,Hollandse_Noord!AO14,Dieppe!AN14,'Moray Firth'!AO14,Kriegers!AO14,'East Anglia One'!AO14) -> 0.035280423 | AF14: =AVERAGE('Horns Rev'!AP14,Seagreen!AP14,Gemini!AP14,Hollandse_Noord!AP14,Dieppe!AO14,'Moray Firth'!AP14,Kriegers!AP14,'East Anglia One'!AP14) -> 0.95804167 | AG14: =AVERAGE('Horns Rev'!AR14,Seagreen!AR14,Gemini!AR14,Hollandse_Noord!AR14,Dieppe!AQ14,'Moray Firth'!AR14,Kriegers!AR14,'East Anglia One'!AR14) -> 25.725 | AH14: =AVERAGE('Horns Rev'!AS14,Seagreen!AS14,Gemini!AS14,Hollandse_Noord!AS14,Dieppe!AR14,'Moray Firth'!AS14,Kriegers!AS14,'East Anglia One'!AS14) -> 0.034514968 | AI14: =AVERAGE('Horns Rev'!AT14,Seagreen!AT14,Gemini!AT14,Hollandse_Noord!AT14,Dieppe!AS14,'Moray Firth'!AT14,Kriegers!AT14,'East Anglia One'!AT14) -> 0.95933333
B15: 6 | C15: =AVERAGE('Horns Rev'!D15,Seagreen!D15,Gemini!D15,Hollandse_Noord!D15,Dieppe!D15,'Moray Firth'!D15,Kriegers!D15,'East Anglia One'!D15) -> 35.575 | D15: =AVERAGE('Horns Rev'!E15,Seagreen!E15,Gemini!E15,Hollandse_Noord!E15,Dieppe!E15,'Moray Firth'!E15,Kriegers!E15,'East Anglia One'!E15) -> 0.047987218 | E15: =AVERAGE('Horns Rev'!F15,Seagreen!F15,Gemini!F15,Hollandse_Noord!F15,Dieppe!F15,'Moray Firth'!F15,Kriegers!F15,'East Anglia One'!F15) -> 0.922875 | F15: =AVERAGE('Horns Rev'!H15,Seagreen!H15,Gemini!H15,Hollandse_Noord!H15,Dieppe!H15,'Moray Firth'!H15,Kriegers!H15,'East Anglia One'!H15) -> 27.583333 | G15: =AVERAGE('Horns Rev'!I15,Seagreen!I15,Gemini!I15,Hollandse_Noord!I15,Dieppe!I15,'Moray Firth'!I15,Kriegers!I15,'East Anglia One'!I15) -> 0.036765249 | H15: =AVERAGE('Horns Rev'!J15,Seagreen!J15,Gemini!J15,Hollandse_Noord!J15,Dieppe!J15,'Moray Firth'!J15,Kriegers!J15,'East Anglia One'!J15) -> 0.9565 | I15: =AVERAGE('Horns Rev'!L15,Seagreen!L15,Gemini!L15,Hollandse_Noord!L15,Dieppe!L15,'Moray Firth'!L15,Kriegers!L15,'East Anglia One'!L15) -> 25.8625 | J15: =AVERAGE('Horns Rev'!M15,Seagreen!M15,Gemini!M15,Hollandse_Noord!M15,Dieppe!M15,'Moray Firth'!M15,Kriegers!M15,'East Anglia One'!M15) -> 0.034334925 | K15: =AVERAGE('Horns Rev'!N15,Seagreen!N15,Gemini!N15,Hollandse_Noord!N15,Dieppe!N15,'Moray Firth'!N15,Kriegers!N15,'East Anglia One'!N15) -> 0.96225 | L15: =AVERAGE('Horns Rev'!P15,Seagreen!P15,Gemini!P15,Hollandse_Noord!P15,Dieppe!P15,'Moray Firth'!P15,Kriegers!P15,'East Anglia One'!P15) -> 24.925 | M15: =AVERAGE('Horns Rev'!Q15,Seagreen!Q15,Gemini!Q15,Hollandse_Noord!Q15,Dieppe!Q15,'Moray Firth'!Q15,Kriegers!Q15,'East Anglia One'!Q15) -> 0.033059271 | N15: =AVERAGE('Horns Rev'!R15,Seagreen!R15,Gemini!R15,Hollandse_Noord!R15,Dieppe!R15,'Moray Firth'!R15,Kriegers!R15,'East Anglia One'!R15) -> 0.96358333 | O15: =AVERAGE('Horns Rev'!T15,Seagreen!T15,Gemini!T15,Hollandse_Noord!T15,Dieppe!T15,'Moray Firth'!T15,Kriegers!T15,'East Anglia One'!T15) -> 24.629167 | P15: =AVERAGE('Horns Rev'!U15,Seagreen!U15,Gemini!U15,Hollandse_Noord!U15,Dieppe!U15,'Moray Firth'!U15,Kriegers!U15,'East Anglia One'!U15) -> 0.032776811 | Q15: =AVERAGE('Horns Rev'!V15,Seagreen!V15,Gemini!V15,Hollandse_Noord!V15,Dieppe!V15,'Moray Firth'!V15,Kriegers!V15,'East Anglia One'!V15) -> 0.96466667 | T15: 6 | U15: =AVERAGE('Horns Rev'!AB15,Seagreen!AB15,Gemini!AB15,Hollandse_Noord!AB15,Dieppe!AA15,'Moray Firth'!AB15,Kriegers!AB15,'East Anglia One'!AB15) -> 43.1375 | V15: =AVERAGE('Horns Rev'!AC15,Seagreen!AC15,Gemini!AC15,Hollandse_Noord!AC15,Dieppe!AB15,'Moray Firth'!AC15,Kriegers!AC15,'East Anglia One'!AC15) -> 0.057430217 | W15: =AVERAGE('Horns Rev'!AD15,Seagreen!AD15,Gemini!AD15,Hollandse_Noord!AD15,Dieppe!AC15,'Moray Firth'!AD15,Kriegers!AD15,'East Anglia One'!AD15) -> 0.89716667 | X15: =AVERAGE('Horns Rev'!AF15,Seagreen!AF15,Gemini!AF15,Hollandse_Noord!AF15,Dieppe!AE15,'Moray Firth'!AF15,Kriegers!AF15,'East Anglia One'!AF15) -> 32.308333 | Y15: =AVERAGE('Horns Rev'!AG15,Seagreen!AG15,Gemini!AG15,Hollandse_Noord!AG15,Dieppe!AF15,'Moray Firth'!AG15,Kriegers!AG15,'East Anglia One'!AG15) -> 0.043068193 | Z15: =AVERAGE('Horns Rev'!AH15,Seagreen!AH15,Gemini!AH15,Hollandse_Noord!AH15,Dieppe!AG15,'Moray Firth'!AH15,Kriegers!AH15,'East Anglia One'!AH15) -> 0.94291667 | AA15: =AVERAGE('Horns Rev'!AJ15,Seagreen!AJ15,Gemini!AJ15,Hollandse_Noord!AJ15,Dieppe!AI15,'Moray Firth'!AJ15,Kriegers!AJ15,'East Anglia One'!AJ15) -> 29.395833 | AB15: =AVERAGE('Horns Rev'!AK15,Seagreen!AK15,Gemini!AK15,Hollandse_Noord!AK15,Dieppe!AJ15,'Moray Firth'!AK15,Kriegers!AK15,'East Anglia One'!AK15) -> 0.038973906 | AC15: =AVERAGE('Horns Rev'!AL15,Seagreen!AL15,Gemini!AL15,Hollandse_Noord!AL15,Dieppe!AK15,'Moray Firth'!AL15,Kriegers!AL15,'East Anglia One'!AL15) -> 0.952875 | AD15: =AVERAGE('Horns Rev'!AN15,Seagreen!AN15,Gemini!AN15,Hollandse_Noord!AN15,Dieppe!AM15,'Moray Firth'!AN15,Kriegers!AN15,'East Anglia One'!AN15) -> 27.591667 | AE15: =AVERAGE('Horns Rev'!AO15,Seagreen!AO15,Gemini!AO15,Hollandse_Noord!AO15,Dieppe!AN15,'Moray Firth'!AO15,Kriegers!AO15,'East Anglia One'!AO15) -> 0.036491494 | AF15: =AVERAGE('Horns Rev'!AP15,Seagreen!AP15,Gemini!AP15,Hollandse_Noord!AP15,Dieppe!AO15,'Moray Firth'!AP15,Kriegers!AP15,'East Anglia One'!AP15) -> 0.95845833 | AG15: =AVERAGE('Horns Rev'!AR15,Seagreen!AR15,Gemini!AR15,Hollandse_Noord!AR15,Dieppe!AQ15,'Moray Firth'!AR15,Kriegers!AR15,'East Anglia One'!AR15) -> 27.033333 | AH15: =AVERAGE('Horns Rev'!AS15,Seagreen!AS15,Gemini!AS15,Hollandse_Noord!AS15,Dieppe!AR15,'Moray Firth'!AS15,Kriegers!AS15,'East Anglia One'!AS15) -> 0.035875439 | AI15: =AVERAGE('Horns Rev'!AT15,Seagreen!AT15,Gemini!AT15,Hollandse_Noord!AT15,Dieppe!AS15,'Moray Firth'!AT15,Kriegers!AT15,'East Anglia One'!AT15) -> 0.96041667
B16: 7 | C16: =AVERAGE('Horns Rev'!D16,Seagreen!D16,Gemini!D16,Hollandse_Noord!D16,Dieppe!D16,'Moray Firth'!D16,Kriegers!D16,'East Anglia One'!D16) -> 47.741667 | D16: =AVERAGE('Horns Rev'!E16,Seagreen!E16,Gemini!E16,Hollandse_Noord!E16,Dieppe!E16,'Moray Firth'!E16,Kriegers!E16,'East Anglia One'!E16) -> 0.057792965 | E16: =AVERAGE('Horns Rev'!F16,Seagreen!F16,Gemini!F16,Hollandse_Noord!F16,Dieppe!F16,'Moray Firth'!F16,Kriegers!F16,'East Anglia One'!F16) -> 0.83433333 | F16: =AVERAGE('Horns Rev'!H16,Seagreen!H16,Gemini!H16,Hollandse_Noord!H16,Dieppe!H16,'Moray Firth'!H16,Kriegers!H16,'East Anglia One'!H16) -> 29.416667 | G16: =AVERAGE('Horns Rev'!I16,Seagreen!I16,Gemini!I16,Hollandse_Noord!I16,Dieppe!I16,'Moray Firth'!I16,Kriegers!I16,'East Anglia One'!I16) -> 0.037619115 | H16: =AVERAGE('Horns Rev'!J16,Seagreen!J16,Gemini!J16,Hollandse_Noord!J16,Dieppe!J16,'Moray Firth'!J16,Kriegers!J16,'East Anglia One'!J16) -> 0.931875 | I16: =AVERAGE('Horns Rev'!L16,Seagreen!L16,Gemini!L16,Hollandse_Noord!L16,Dieppe!L16,'Moray Firth'!L16,Kriegers!L16,'East Anglia One'!L16) -> 26.758333 | J16: =AVERAGE('Horns Rev'!M16,Seagreen!M16,Gemini!M16,Hollandse_Noord!M16,Dieppe!M16,'Moray Firth'!M16,Kriegers!M16,'East Anglia One'!M16) -> 0.034294169 | K16: =AVERAGE('Horns Rev'!N16,Seagreen!N16,Gemini!N16,Hollandse_Noord!N16,Dieppe!N16,'Moray Firth'!N16,Kriegers!N16,'East Anglia One'!N16) -> 0.94145833 | L16: =AVERAGE('Horns Rev'!P16,Seagreen!P16,Gemini!P16,Hollandse_Noord!P16,Dieppe!P16,'Moray Firth'!P16,Kriegers!P16,'East Anglia One'!P16) -> 24.520833 | M16: =AVERAGE('Horns Rev'!Q16,Seagreen!Q16,Gemini!Q16,Hollandse_Noord!Q16,Dieppe!Q16,'Moray Firth'!Q16,Kriegers!Q16,'East Anglia One'!Q16) -> 0.031889582 | N16: =AVERAGE('Horns Rev'!R16,Seagreen!R16,Gemini!R16,Hollandse_Noord!R16,Dieppe!R16,'Moray Firth'!R16,Kriegers!R16,'East Anglia One'!R16) -> 0.94708333 | O16: =AVERAGE('Horns Rev'!T16,Seagreen!T16,Gemini!T16,Hollandse_Noord!T16,Dieppe!T16,'Moray Firth'!T16,Kriegers!T16,'East Anglia One'!T16) -> 24.029167 | P16: =AVERAGE('Horns Rev'!U16,Seagreen!U16,Gemini!U16,Hollandse_Noord!U16,Dieppe!U16,'Moray Firth'!U16,Kriegers!U16,'East Anglia One'!U16) -> 0.031273335 | Q16: =AVERAGE('Horns Rev'!V16,Seagreen!V16,Gemini!V16,Hollandse_Noord!V16,Dieppe!V16,'Moray Firth'!V16,Kriegers!V16,'East Anglia One'!V16) -> 0.94970833 | T16: 7 | U16: =AVERAGE('Horns Rev'!AB16,Seagreen!AB16,Gemini!AB16,Hollandse_Noord!AB16,Dieppe!AA16,'Moray Firth'!AB16,Kriegers!AB16,'East Anglia One'!AB16) -> 60.870833 | V16: =AVERAGE('Horns Rev'!AC16,Seagreen!AC16,Gemini!AC16,Hollandse_Noord!AC16,Dieppe!AB16,'Moray Firth'!AC16,Kriegers!AC16,'East Anglia One'!AC16) -> 0.074813173 | W16: =AVERAGE('Horns Rev'!AD16,Seagreen!AD16,Gemini!AD16,Hollandse_Noord!AD16,Dieppe!AC16,'Moray Firth'!AD16,Kriegers!AD16,'East Anglia One'!AD16) -> 0.77616667 | X16: =AVERAGE('Horns Rev'!AF16,Seagreen!AF16,Gemini!AF16,Hollandse_Noord!AF16,Dieppe!AE16,'Moray Firth'!AF16,Kriegers!AF16,'East Anglia One'!AF16) -> 35.991667 | Y16: =AVERAGE('Horns Rev'!AG16,Seagreen!AG16,Gemini!AG16,Hollandse_Noord!AG16,Dieppe!AF16,'Moray Firth'!AG16,Kriegers!AG16,'East Anglia One'!AG16) -> 0.046311902 | Z16: =AVERAGE('Horns Rev'!AH16,Seagreen!AH16,Gemini!AH16,Hollandse_Noord!AH16,Dieppe!AG16,'Moray Firth'!AH16,Kriegers!AH16,'East Anglia One'!AH16) -> 0.90575 | AA16: =AVERAGE('Horns Rev'!AJ16,Seagreen!AJ16,Gemini!AJ16,Hollandse_Noord!AJ16,Dieppe!AI16,'Moray Firth'!AJ16,Kriegers!AJ16,'East Anglia One'!AJ16) -> 31.816667 | AB16: =AVERAGE('Horns Rev'!AK16,Seagreen!AK16,Gemini!AK16,Hollandse_Noord!AK16,Dieppe!AJ16,'Moray Firth'!AK16,Kriegers!AK16,'East Anglia One'!AK16) -> 0.040886522 | AC16: =AVERAGE('Horns Rev'!AL16,Seagreen!AL16,Gemini!AL16,Hollandse_Noord!AL16,Dieppe!AK16,'Moray Firth'!AL16,Kriegers!AL16,'East Anglia One'!AL16) -> 0.923625 | AD16: =AVERAGE('Horns Rev'!AN16,Seagreen!AN16,Gemini!AN16,Hollandse_Noord!AN16,Dieppe!AM16,'Moray Firth'!AN16,Kriegers!AN16,'East Anglia One'!AN16) -> 28.533333 | AE16: =AVERAGE('Horns Rev'!AO16,Seagreen!AO16,Gemini!AO16,Hollandse_Noord!AO16,Dieppe!AN16,'Moray Firth'!AO16,Kriegers!AO16,'East Anglia One'!AO16) -> 0.036947624 | AF16: =AVERAGE('Horns Rev'!AP16,Seagreen!AP16,Gemini!AP16,Hollandse_Noord!AP16,Dieppe!AO16,'Moray Firth'!AP16,Kriegers!AP16,'East Anglia One'!AP16) -> 0.93516667 | AG16: =AVERAGE('Horns Rev'!AR16,Seagreen!AR16,Gemini!AR16,Hollandse_Noord!AR16,Dieppe!AQ16,'Moray Firth'!AR16,Kriegers!AR16,'East Anglia One'!AR16) -> 27.441667 | AH16: =AVERAGE('Horns Rev'!AS16,Seagreen!AS16,Gemini!AS16,Hollandse_Noord!AS16,Dieppe!AR16,'Moray Firth'!AS16,Kriegers!AS16,'East Anglia One'!AS16) -> 0.035466622 | AI16: =AVERAGE('Horns Rev'!AT16,Seagreen!AT16,Gemini!AT16,Hollandse_Noord!AT16,Dieppe!AS16,'Moray Firth'!AT16,Kriegers!AT16,'East Anglia One'!AT16) -> 0.94020833
B18: Average | C18: =AVERAGE('Horns Rev'!D18,Seagreen!D18,Gemini!D18,Hollandse_Noord!D18,Dieppe!D18,'Moray Firth'!D18,Kriegers!D18,'East Anglia One'!D18) -> 32.918928 | D18: =AVERAGE('Horns Rev'!E18,Seagreen!E18,Gemini!E18,Hollandse_Noord!E18,Dieppe!E18,'Moray Firth'!E18,Kriegers!E18,'East Anglia One'!E18) -> 0.043370567 | E18: =AVERAGE('Horns Rev'!F18,Seagreen!F18,Gemini!F18,Hollandse_Noord!F18,Dieppe!F18,'Moray Firth'!F18,Kriegers!F18,'East Anglia One'!F18) -> 0.93332501 | F18: =AVERAGE('Horns Rev'!H18,Seagreen!H18,Gemini!H18,Hollandse_Noord!H18,Dieppe!H18,'Moray Firth'!H18,Kriegers!H18,'East Anglia One'!H18) -> 26.711088 | G18: =AVERAGE('Horns Rev'!I18,Seagreen!I18,Gemini!I18,Hollandse_Noord!I18,Dieppe!I18,'Moray Firth'!I18,Kriegers!I18,'East Anglia One'!I18) -> 0.03520736 | H18: =AVERAGE('Horns Rev'!J18,Seagreen!J18,Gemini!J18,Hollandse_Noord!J18,Dieppe!J18,'Moray Firth'!J18,Kriegers!J18,'East Anglia One'!J18) -> 0.95606662 | I18: =AVERAGE('Horns Rev'!L18,Seagreen!L18,Gemini!L18,Hollandse_Noord!L18,Dieppe!L18,'Moray Firth'!L18,Kriegers!L18,'East Anglia One'!L18) -> 25.00948 | J18: =AVERAGE('Horns Rev'!M18,Seagreen!M18,Gemini!M18,Hollandse_Noord!M18,Dieppe!M18,'Moray Firth'!M18,Kriegers!M18,'East Anglia One'!M18) -> 0.032962002 | K18: =AVERAGE('Horns Rev'!N18,Seagreen!N18,Gemini!N18,Hollandse_Noord!N18,Dieppe!N18,'Moray Firth'!N18,Kriegers!N18,'East Anglia One'!N18) -> 0.96047801 | L18: =AVERAGE('Horns Rev'!P18,Seagreen!P18,Gemini!P18,Hollandse_Noord!P18,Dieppe!P18,'Moray Firth'!P18,Kriegers!P18,'East Anglia One'!P18) -> 24.494724 | M18: =AVERAGE('Horns Rev'!Q18,Seagreen!Q18,Gemini!Q18,Hollandse_Noord!Q18,Dieppe!Q18,'Moray Firth'!Q18,Kriegers!Q18,'East Anglia One'!Q18) -> 0.032282391 | N18: =AVERAGE('Horns Rev'!R18,Seagreen!R18,Gemini!R18,Hollandse_Noord!R18,Dieppe!R18,'Moray Firth'!R18,Kriegers!R18,'East Anglia One'!R18) -> 0.96261762 | O18: =AVERAGE('Horns Rev'!T18,Seagreen!T18,Gemini!T18,Hollandse_Noord!T18,Dieppe!T18,'Moray Firth'!T18,Kriegers!T18,'East Anglia One'!T18) -> 24.4341 | P18: =AVERAGE('Horns Rev'!U18,Seagreen!U18,Gemini!U18,Hollandse_Noord!U18,Dieppe!U18,'Moray Firth'!U18,Kriegers!U18,'East Anglia One'!U18) -> 0.032203421 | Q18: =AVERAGE('Horns Rev'!V18,Seagreen!V18,Gemini!V18,Hollandse_Noord!V18,Dieppe!V18,'Moray Firth'!V18,Kriegers!V18,'East Anglia One'!V18) -> 0.96305943 | T18: Average | U18: =AVERAGE('Horns Rev'!AB18,Seagreen!AB18,Gemini!AB18,Hollandse_Noord!AB18,Dieppe!AA18,'Moray Firth'!AB18,Kriegers!AB18,'East Anglia One'!AB18) -> 40.032613 | V18: =AVERAGE('Horns Rev'!AC18,Seagreen!AC18,Gemini!AC18,Hollandse_Noord!AC18,Dieppe!AB18,'Moray Firth'!AC18,Kriegers!AC18,'East Anglia One'!AC18) -> 0.052598948 | W18: =AVERAGE('Horns Rev'!AD18,Seagreen!AD18,Gemini!AD18,Hollandse_Noord!AD18,Dieppe!AC18,'Moray Firth'!AD18,Kriegers!AD18,'East Anglia One'!AD18) -> 0.91100584 | X18: =AVERAGE('Horns Rev'!AF18,Seagreen!AF18,Gemini!AF18,Hollandse_Noord!AF18,Dieppe!AE18,'Moray Firth'!AF18,Kriegers!AF18,'East Anglia One'!AF18) -> 31.331544 | Y18: =AVERAGE('Horns Rev'!AG18,Seagreen!AG18,Gemini!AG18,Hollandse_Noord!AG18,Dieppe!AF18,'Moray Firth'!AG18,Kriegers!AG18,'East Anglia One'!AG18) -> 0.04127139 | Z18: =AVERAGE('Horns Rev'!AH18,Seagreen!AH18,Gemini!AH18,Hollandse_Noord!AH18,Dieppe!AG18,'Moray Firth'!AH18,Kriegers!AH18,'East Anglia One'!AH18) -> 0.94540115 | AA18: =AVERAGE('Horns Rev'!AJ18,Seagreen!AJ18,Gemini!AJ18,Hollandse_Noord!AJ18,Dieppe!AI18,'Moray Firth'!AJ18,Kriegers!AJ18,'East Anglia One'!AJ18) -> 28.401864 | AB18: =AVERAGE('Horns Rev'!AK18,Seagreen!AK18,Gemini!AK18,Hollandse_Noord!AK18,Dieppe!AJ18,'Moray Firth'!AK18,Kriegers!AK18,'East Anglia One'!AK18) -> 0.037405516 | AC18: =AVERAGE('Horns Rev'!AL18,Seagreen!AL18,Gemini!AL18,Hollandse_Noord!AL18,Dieppe!AK18,'Moray Firth'!AL18,Kriegers!AL18,'East Anglia One'!AL18) -> 0.95284622 | AD18: =AVERAGE('Horns Rev'!AN18,Seagreen!AN18,Gemini!AN18,Hollandse_Noord!AN18,Dieppe!AM18,'Moray Firth'!AN18,Kriegers!AN18,'East Anglia One'!AN18) -> 27.299048 | AE18: =AVERAGE('Horns Rev'!AO18,Seagreen!AO18,Gemini!AO18,Hollandse_Noord!AO18,Dieppe!AN18,'Moray Firth'!AO18,Kriegers!AO18,'East Anglia One'!AO18) -> 0.035901656 | AF18: =AVERAGE('Horns Rev'!AP18,Seagreen!AP18,Gemini!AP18,Hollandse_Noord!AP18,Dieppe!AO18,'Moray Firth'!AP18,Kriegers!AP18,'East Anglia One'!AP18) -> 0.95717407 | AG18: =AVERAGE('Horns Rev'!AR18,Seagreen!AR18,Gemini!AR18,Hollandse_Noord!AR18,Dieppe!AQ18,'Moray Firth'!AR18,Kriegers!AR18,'East Anglia One'!AR18) -> 26.980859 | AH18: =AVERAGE('Horns Rev'!AS18,Seagreen!AS18,Gemini!AS18,Hollandse_Noord!AS18,Dieppe!AR18,'Moray Firth'!AS18,Kriegers!AS18,'East Anglia One'!AS18) -> 0.035527308 | AI18: =AVERAGE('Horns Rev'!AT18,Seagreen!AT18,Gemini!AT18,Hollandse_Noord!AT18,Dieppe!AS18,'Moray Firth'!AT18,Kriegers!AT18,'East Anglia One'!AT18) -> 0.95857238
C32: 0.1 | K32: 0.2 | S32: 0.3 | AA32: 0.4 | AI32: 0.5
B33: Clusters | C33: Horns | D33: Seagreen | E33: Gemini | F33: Hollandse | G33: Dieppe | H33: Moray | I33: Kriegers | J33: East.Anglia | K33: Horns | L33: Seagreen | M33: Gemini | N33: Hollandse | O33: Dieppe | P33: Moray | Q33: Kriegers | R33: East.Anglia | S33: Horns | T33: Seagreen | U33: Gemini | V33: Hollandse | W33: Dieppe | X33: Moray | Y33: Kriegers | Z33: East.Anglia | AA33: Horns | AB33: Seagreen | AC33: Gemini | AD33: Hollandse | AE33: Dieppe | AF33: Moray | AG33: Kriegers | AH33: East.Anglia | AI33: Horns | AJ33: Seagreen | AK33: Gemini | AL33: Hollandse | AM33: Dieppe | AN33: Moray | AO33: Kriegers | AP33: East.Anglia
B34: 0 | C34: ='Horns Rev'!E9 -> 0.052629274 | D34: =Seagreen!E9 -> 0.045833333 | E34: =Gemini!E9 -> 0.042666667 | F34: =Hollandse_Noord!E9 -> 0.040623628 | G34: =Dieppe!E9 -> 0.04327957 | H34: ='Moray Firth'!E9 -> 0.044492378 | I34: =Kriegers!E9 -> 0.042476852 | J34: ='East Anglia One'!E9 -> 0.03898226 | K34: ='Horns Rev'!I9 -> 0.039668987 | L34: =Seagreen!I9 -> 0.038685897 | M34: =Gemini!I9 -> 0.033 | N34: =Hollandse_Noord!I9 -> 0.037241985 | O34: =Dieppe!I9 -> 0.037365591 | P34: ='Moray Firth'!I9 -> 0.040264596 | Q34: =Kriegers!I9 -> 0.039236111 | R34: ='East Anglia One'!I9 -> 0.034360411 | S34: ='Horns Rev'!M9 -> 0.034940234 | T34: =Seagreen!M9 -> 0.034679487 | U34: =Gemini!M9 -> 0.031444444 | V34: =Hollandse_Noord!M9 -> 0.03697848 | W34: =Dieppe!M9 -> 0.035013441 | X34: ='Moray Firth'!M9 -> 0.037446074 | Y34: =Kriegers!M9 -> 0.0359375 | Z34: ='East Anglia One'!M9 -> 0.034080299 | AA34: ='Horns Rev'!Q9 -> 0.034677525 | AB34: =Seagreen!Q9 -> 0.036314103 | AC34: =Gemini!Q9 -> 0.033055556 | AD34: =Hollandse_Noord!Q9 -> 0.037198068 | AE34: =Dieppe!Q9 -> 0.034610215 | AF34: ='Moray Firth'!Q9 -> 0.036784584 | AG34: =Kriegers!Q9 -> 0.036342593 | AH34: ='East Anglia One'!Q9 -> 0.03225957 | AI34: ='Horns Rev'!U9 -> 0.033758045 | AJ34: =Seagreen!U9 -> 0.034519231 | AK34: =Gemini!U9 -> 0.030055556 | AL34: =Hollandse_Noord!U9 -> 0.038120334 | AM34: =Dieppe!U9 -> 0.036693548 | AN34: ='Moray Firth'!U9 -> 0.036842105 | AO34: =Kriegers!U9 -> 0.037962963 | AP34: ='East Anglia One'!U9 -> 0.033940243
B35: 1 | C35: ='Horns Rev'!E10 -> 0.037435965 | D35: =Seagreen!E10 -> 0.033942308 | E35: =Gemini!E10 -> 0.041666667 | F35: =Hollandse_Noord!E10 -> 0.035924462 | G35: =Dieppe!E10 -> 0.042204301 | H35: ='Moray Firth'!E10 -> 0.035864251 | I35: =Kriegers!E10 -> 0.037673611 | J35: ='East Anglia One'!E10 -> 0.034640523 | K35: ='Horns Rev'!I10 -> 0.030693113 | L35: =Seagreen!I10 -> 0.031217949 | M35: =Gemini!I10 -> 0.034111111 | N35: =Hollandse_Noord!I10 -> 0.034255599 | O35: =Dieppe!I10 -> 0.034206989 | P35: ='Moray Firth'!I10 -> 0.030658614 | Q35: =Kriegers!I10 -> 0.035300926 | R35: ='East Anglia One'!I10 -> 0.033706816 | S35: ='Horns Rev'!M10 -> 0.029029292 | T35: =Seagreen!M10 -> 0.029679487 | U35: =Gemini!M10 -> 0.032722222 | V35: =Hollandse_Noord!M10 -> 0.034387352 | W35: =Dieppe!M10 -> 0.034139785 | X35: ='Moray Firth'!M10 -> 0.028760426 | Y35: =Kriegers!M10 -> 0.035590278 | Z35: ='East Anglia One'!M10 -> 0.030625584 | AA35: ='Horns Rev'!Q10 -> 0.028854153 | AB35: =Seagreen!Q10 -> 0.029391026 | AC35: =Gemini!Q10 -> 0.032833333 | AD35: =Hollandse_Noord!Q10 -> 0.032630654 | AE35: =Dieppe!Q10 -> 0.032392473 | AF35: ='Moray Firth'!Q10 -> 0.029910843 | AG35: =Kriegers!Q10 -> 0.0359375 | AH35: ='East Anglia One'!Q10 -> 0.031652661 | AI35: ='Horns Rev'!U10 -> 0.029029292 | AJ35: =Seagreen!U10 -> 0.028621795 | AK35: =Gemini!U10 -> 0.032388889 | AL35: =Hollandse_Noord!U10 -> 0.033684673 | AM35: =Dieppe!U10 -> 0.033669355 | AN35: ='Moray Firth'!U10 -> 0.029134311 | AO35: =Kriegers!U10 -> 0.034837963 | AP35: ='East Anglia One'!U10 -> 0.029645191
B36: 2 | C36: ='Horns Rev'!E11 -> 0.04181444 | D36: =Seagreen!E11 -> 0.038012821 | E36: =Gemini!E11 -> 0.024111111 | F36: =Hollandse_Noord!E11 -> 0.045630215 | G36: =Dieppe!E11 -> 0.046034946 | H36: ='Moray Firth'!E11 -> 0.036266897 | I36: =Kriegers!E11 -> 0.036111111 | J36: ='East Anglia One'!E11 -> 0.045751634 | K36: ='Horns Rev'!I11 -> 0.032926135 | L36: =Seagreen!I11 -> 0.034903846 | M36: =Gemini!I11 -> 0.022111111 | N36: =Hollandse_Noord!I11 -> 0.034782609 | O36: =Dieppe!I11 -> 0.036424731 | P36: ='Moray Firth'!I11 -> 0.032901927 | Q36: =Kriegers!I11 -> 0.030555556 | R36: ='East Anglia One'!I11 -> 0.035060691 | S36: ='Horns Rev'!M11 -> 0.031262314 | T36: =Seagreen!M11 -> 0.030512821 | U36: =Gemini!M11 -> 0.021611111 | V36: =Hollandse_Noord!M11 -> 0.031884058 | W36: =Dieppe!M11 -> 0.03219086 | X36: ='Moray Firth'!M11 -> 0.032240437 | Y36: =Kriegers!M11 -> 0.028877315 | Z36: ='East Anglia One'!M11 -> 0.032119514 | AA36: ='Horns Rev'!Q11 -> 0.029335785 | AB36: =Seagreen!Q11 -> 0.031057692 | AC36: =Gemini!Q11 -> 0.020611111 | AD36: =Hollandse_Noord!Q11 -> 0.030873957 | AE36: =Dieppe!Q11 -> 0.028830645 | AF36: ='Moray Firth'!Q11 -> 0.032154156 | AG36: =Kriegers!Q11 -> 0.026967593 | AH36: ='East Anglia One'!Q11 -> 0.033473389 | AI36: ='Horns Rev'!U11 -> 0.028328736 | AJ36: =Seagreen!U11 -> 0.03224359 | AK36: =Gemini!U11 -> 0.019444444 | AL36: =Hollandse_Noord!U11 -> 0.033113746 | AM36: =Dieppe!U11 -> 0.029502688 | AN36: ='Moray Firth'!U11 -> 0.032643083 | AO36: =Kriegers!U11 -> 0.0265625 | AP36: ='East Anglia One'!U11 -> 0.032913165
B37: 3 | C37: ='Horns Rev'!E12 -> 0.040632252 | D37: =Seagreen!E12 -> 0.047916667 | E37: =Gemini!E12 -> 0.042611111 | F37: =Hollandse_Noord!E12 -> 0.054896794 | G37: =Dieppe!E12 -> 0.052217742 | H37: ='Moray Firth'!E12 -> 0.03580673 | I37: =Kriegers!E12 -> 0.0484375 | J37: ='East Anglia One'!E12 -> 0.040289449 | K37: ='Horns Rev'!I12 -> 0.032400718 | L37: =Seagreen!I12 -> 0.032532051 | M37: =Gemini!I12 -> 0.034277778 | N37: =Hollandse_Noord!I12 -> 0.036407554 | O37: =Dieppe!I12 -> 0.043010753 | P37: ='Moray Firth'!I12 -> 0.031578947 | Q37: =Kriegers!I12 -> 0.046875 | R37: ='East Anglia One'!I12 -> 0.035154062 | S37: ='Horns Rev'!M12 -> 0.031174745 | T37: =Seagreen!M12 -> 0.031153846 | U37: =Gemini!M12 -> 0.031277778 | V37: =Hollandse_Noord!M12 -> 0.03236715 | W37: =Dieppe!M12 -> 0.03702957 | X37: ='Moray Firth'!M12 -> 0.030831176 | Y37: =Kriegers!M12 -> 0.038831019 | Z37: ='East Anglia One'!M12 -> 0.030532213 | AA37: ='Horns Rev'!Q12 -> 0.030649328 | AB37: =Seagreen!Q12 -> 0.031057692 | AC37: =Gemini!Q12 -> 0.031611111 | AD37: =Hollandse_Noord!Q12 -> 0.032498902 | AE37: =Dieppe!Q12 -> 0.035887097 | AF37: ='Moray Firth'!Q12 -> 0.028731665 | AG37: =Kriegers!Q12 -> 0.038946759 | AH37: ='East Anglia One'!Q12 -> 0.029225023 | AI37: ='Horns Rev'!U12 -> 0.029160646 | AJ37: =Seagreen!U12 -> 0.032275641 | AK37: =Gemini!U12 -> 0.030555556 | AL37: =Hollandse_Noord!U12 -> 0.033552921 | AM37: =Dieppe!U12 -> 0.033736559 | AN37: ='Moray Firth'!U12 -> 0.030457291 | AO37: =Kriegers!U12 -> 0.039930556 | AP37: ='East Anglia One'!U12 -> 0.028664799
B38: 4 | C38: ='Horns Rev'!E13 -> 0.045711283 | D38: =Seagreen!E13 -> 0.044326923 | E38: =Gemini!E13 -> 0.054833333 | F38: =Hollandse_Noord!E13 -> 0.043917435 | G38: =Dieppe!E13 -> 0.051209677 | H38: ='Moray Firth'!E13 -> 0.039574346 | I38: =Kriegers!E13 -> 0.085011574 | J38: ='East Anglia One'!E13 -> 0.040756303 | K38: ='Horns Rev'!I13 -> 0.03822409 | L38: =Seagreen!I13 -> 0.032147436 | M38: =Gemini!I13 -> 0.044444444 | N38: =Hollandse_Noord!I13 -> 0.037856829 | O38: =Dieppe!I13 -> 0.04327957 | P38: ='Moray Firth'!I13 -> 0.036410699 | Q38: =Kriegers!I13 -> 0.042361111 | R38: ='East Anglia One'!I13 -> 0.034733894 | S38: ='Horns Rev'!M13 -> 0.035991068 | T38: =Seagreen!M13 -> 0.03125 | U38: =Gemini!M13 -> 0.037944444 | V38: =Hollandse_Noord!M13 -> 0.034387352 | W38: =Dieppe!M13 -> 0.038239247 | X38: ='Moray Firth'!M13 -> 0.031233822 | Y38: =Kriegers!M13 -> 0.040393519 | Z38: ='East Anglia One'!M13 -> 0.031886088 | AA38: ='Horns Rev'!Q13 -> 0.034458602 | AB38: =Seagreen!Q13 -> 0.030288462 | AC38: =Gemini!Q13 -> 0.036055556 | AD38: =Hollandse_Noord!Q13 -> 0.034431269 | AE38: =Dieppe!Q13 -> 0.036290323 | AF38: ='Moray Firth'!Q13 -> 0.031003739 | AG38: =Kriegers!Q13 -> 0.039583333 | AH38: ='East Anglia One'!Q13 -> 0.03076564 | AI38: ='Horns Rev'!U13 -> 0.034020754 | AJ38: =Seagreen!U13 -> 0.03125 | AK38: =Gemini!U13 -> 0.033944444 | AL38: =Hollandse_Noord!U13 -> 0.03579271 | AM38: =Dieppe!U13 -> 0.03702957 | AN38: ='Moray Firth'!U13 -> 0.030744895 | AO38: =Kriegers!U13 -> 0.039409722 | AP38: ='East Anglia One'!U13 -> 0.031699346
B39: 5 | C39: ='Horns Rev'!E14 -> 0.039056001 | D39: =Seagreen!E14 -> 0.044647436 | E39: =Gemini!E14 -> 0.054722222 | F39: =Hollandse_Noord!E14 -> 0.036934563 | G39: =Dieppe!E14 -> 0.051075269 | H39: ='Moray Firth'!E14 -> 0.038682773 | I39: =Kriegers!E14 -> 0.052083333 | J39: ='East Anglia One'!E14 -> 0.039262372 | K39: ='Horns Rev'!I14 -> 0.037654889 | L39: =Seagreen!I14 -> 0.03275641 | M39: =Gemini!I14 -> 0.039277778 | N39: =Hollandse_Noord!I14 -> 0.033421168 | O39: =Dieppe!I14 -> 0.035954301 | P39: ='Moray Firth'!I14 -> 0.030083405 | Q39: =Kriegers!I14 -> 0.045138889 | R39: ='East Anglia One'!I14 -> 0.030578898 | S39: ='Horns Rev'!M14 -> 0.03021148 | T39: =Seagreen!M14 -> 0.029326923 | U39: =Gemini!M14 -> 0.035555556 | V39: =Hollandse_Noord!M14 -> 0.031488801 | W39: =Dieppe!M14 -> 0.034946237 | X39: ='Moray Firth'!M14 -> 0.028329019 | Y39: =Kriegers!M14 -> 0.041724537 | Z39: ='East Anglia One'!M14 -> 0.028384687 | AA39: ='Horns Rev'!Q14 -> 0.029642279 | AB39: =Seagreen!Q14 -> 0.026346154 | AC39: =Gemini!Q14 -> 0.034388889 | AD39: =Hollandse_Noord!Q14 -> 0.031357049 | AE39: =Dieppe!Q14 -> 0.034139785 | AF39: ='Moray Firth'!Q14 -> 0.026459592 | AG39: =Kriegers!Q14 -> 0.03912037 | AH39: ='East Anglia One'!Q14 -> 0.027077498 | AI39: ='Horns Rev'!U14 -> 0.027978458 | AJ39: =Seagreen!U14 -> 0.025448718 | AK39: =Gemini!U14 -> 0.034555556 | AL39: =Hollandse_Noord!U14 -> 0.032938076 | AM39: =Dieppe!U14 -> 0.031586022 | AN39: ='Moray Firth'!U14 -> 0.027408686 | AO39: =Kriegers!U14 -> 0.038831019 | AP39: ='East Anglia One'!U14 -> 0.028011204
B40: 6 | C40: ='Horns Rev'!E15 -> 0.047462673 | D40: =Seagreen!E15 -> 0.036730769 | E40: =Gemini!E15 -> 0.066611111 | F40: =Hollandse_Noord!E15 -> 0.047738252 | G40: =Dieppe!E15 -> 0.046572581 | H40: ='Moray Firth'!E15 -> 0.043341961 | I40: =Kriegers!E15 -> 0.053703704 | J40: ='East Anglia One'!E15 -> 0.041736695 | K40: ='Horns Rev'!I15 -> 0.033845615 | L40: =Seagreen!I15 -> 0.033012821 | M40: =Gemini!I15 -> 0.041722222 | N40: =Hollandse_Noord!I15 -> 0.03921827 | O40: =Dieppe!I15 -> 0.039583333 | P40: ='Moray Firth'!I15 -> 0.034570032 | Q40: =Kriegers!I15 -> 0.039583333 | R40: ='East Anglia One'!I15 -> 0.032586368 | S40: ='Horns Rev'!M15 -> 0.029642279 | T40: =Seagreen!M15 -> 0.032852564 | U40: =Gemini!M15 -> 0.036111111 | V40: =Hollandse_Noord!M15 -> 0.035221783 | W40: =Dieppe!M15 -> 0.038373656 | X40: ='Moray Firth'!M15 -> 0.033247052 | Y40: =Kriegers!M15 -> 0.037905093 | Z40: ='East Anglia One'!M15 -> 0.031325864 | AA40: ='Horns Rev'!Q15 -> 0.029773633 | AB40: =Seagreen!Q15 -> 0.032019231 | AC40: =Gemini!Q15 -> 0.034055556 | AD40: =Hollandse_Noord!Q15 -> 0.035573123 | AE40: =Dieppe!Q15 -> 0.03561828 | AF40: ='Moray Firth'!Q15 -> 0.030716135 | AG40: =Kriegers!Q15 -> 0.035532407 | AH40: ='East Anglia One'!Q15 -> 0.031185808 | AI40: ='Horns Rev'!U15 -> 0.029423355 | AJ40: =Seagreen!U15 -> 0.030737179 | AK40: =Gemini!U15 -> 0.034666667 | AL40: =Hollandse_Noord!U15 -> 0.036100132 | AM40: =Dieppe!U15 -> 0.035819892 | AN40: ='Moray Firth'!U15 -> 0.030112166 | AO40: =Kriegers!U15 -> 0.035243056 | AP40: ='East Anglia One'!U15 -> 0.030112045
B41: 7 | C41: ='Horns Rev'!E16 -> 0.043040413 | D41: =Seagreen!E16 -> 0.056730769 | E41: =Gemini!E16 -> 0.044222222 | F41: =Hollandse_Noord!E16 -> 0.060122969 | G41: =Dieppe!E16 -> 0.057325269 | H41: ='Moray Firth'!E16 -> 0.11532931 | I41: =Kriegers!E16 -> 0.037673611 | J41: ='East Anglia One'!E16 -> 0.04789916 | K41: ='Horns Rev'!I16 -> 0.030605543 | L41: =Seagreen!I16 -> 0.053717949 | M41: =Gemini!I16 -> 0.026722222 | N41: =Hollandse_Noord!I16 -> 0.036407554 | O41: =Dieppe!I16 -> 0.046034946 | P41: ='Moray Firth'!I16 -> 0.039229221 | Q41: =Kriegers!I16 -> 0.03275463 | R41: ='East Anglia One'!I16 -> 0.035480859 | S41: ='Horns Rev'!M16 -> 0.029116862 | T41: =Seagreen!M16 -> 0.042371795 | U41: =Gemini!M16 -> 0.027222222 | V41: =Hollandse_Noord!M16 -> 0.03561704 | W41: =Dieppe!M16 -> 0.037365591 | X41: ='Moray Firth'!M16 -> 0.038136324 | Y41: =Kriegers!M16 -> 0.031423611 | Z41: ='East Anglia One'!M16 -> 0.033099907 | AA41: ='Horns Rev'!Q16 -> 0.026927624 | AB41: =Seagreen!Q16 -> 0.0325 | AC41: =Gemini!Q16 -> 0.0255 | AD41: =Hollandse_Noord!Q16 -> 0.037198068 | AE41: =Dieppe!Q16 -> 0.035282258 | AF41: ='Moray Firth'!Q16 -> 0.034224907 | AG41: =Kriegers!Q16 -> 0.030150463 | AH41: ='East Anglia One'!Q16 -> 0.033333333 | AI41: ='Horns Rev'!U16 -> 0.026533561 | AJ41: =Seagreen!U16 -> 0.031826923 | AK41: =Gemini!U16 -> 0.024777778 | AL41: =Hollandse_Noord!U16 -> 0.034431269 | AM41: =Dieppe!U16 -> 0.034475806 | AN41: ='Moray Firth'!U16 -> 0.033333333 | AO41: =Kriegers!U16 -> 0.029513889 | AP41: ='East Anglia One'!U16 -> 0.035294118
