Workbook

Sheet Source Results
F5: Seed 42 | I5: Seed 63 | L5: Seed 84
B7: Cluster | C7: Test Samples | D7: GP | E7: RF | F7: Test Samples | G7: GP | H7: RF | I7: Test Samples | J7: GP | K7: RF | L7: Test Samples | M7: GP | N7: RF
B8: 0 | D8: =AVERAGE(G8,J8,M8) -> 3.37 | E8: =AVERAGE(H8,K8,N8) -> 4.0133333 | F8: 2295 | G8: 3.4 | H8: 4.06 | I8: 2215 | J8: 3.76 | K8: 4.56 | L8: 2205 | M8: 2.95 | N8: 3.42
B9: 1 | D9: =AVERAGE(G9,J9,M9) -> 3.2866667 | E9: =AVERAGE(H9,K9,N9) -> 3.71 | F9: 2915 | G9: 3.09 | H9: 3.25 | I9: 2115 | J9: 3.17 | K9: 3.59 | L9: 2245 | M9: 3.6 | N9: 4.29
B10: 2 | D10: =AVERAGE(G10,J10,M10) -> 3.7133333 | E10: =AVERAGE(H10,K10,N10) -> 4.2 | F10: 1570 | G10: 3.3 | H10: 3.77 | I10: 2065 | J10: 3.53 | K10: 4.09 | L10: 2450 | M10: 4.31 | N10: 4.74
B11: 3 | D11: =AVERAGE(G11,J11,M11) -> 3.6966667 | E11: =AVERAGE(H11,K11,N11) -> 4.25 | F11: 2460 | G11: 3.83 | H11: 4.52 | I11: 2040 | J11: 4.04 | K11: 4.69 | L11: 2445 | M11: 3.22 | N11: 3.54
B12: 4 | D12: =AVERAGE(G12,J12,M12) -> 3.3866667 | E12: =AVERAGE(H12,K12,N12) -> 3.8733333 | F12: 3080 | G12: 3.26 | H12: 3.75 | I12: 3385 | J12: 3.27 | K12: 3.58 | L12: 2060 | M12: 3.63 | N12: 4.29
B13: 5 | D13: =AVERAGE(G13,J13,M13) -> 3.9533333 | E13: =AVERAGE(H13,K13,N13) -> 4.5566667 | F13: 1495 | G13: 3.94 | H13: 4.26 | I13: 1395 | J13: 3.67 | K13: 4.59 | L13: 1975 | M13: 4.25 | N13: 4.82
B14: 6 | D14: =AVERAGE(G14,J14,M14) -> 3.3766667 | E14: =AVERAGE(H14,K14,N14) -> 3.92 | F14: 1910 | G14: 3.39 | H14: 4.4 | I14: 2960 | J14: 3.09 | K14: 3.22 | L14: 1955 | M14: 3.65 | N14: 4.14
B15: 7 | D15: =AVERAGE(G15,J15,M15) -> 3.01 | E15: =AVERAGE(H15,K15,N15) -> 3.3133333 | F15: 1760 | G15: 3.12 | H15: 3.49 | I15: 1310 | J15: 3 | K15: 3.56 | L15: 2150 | M15: 2.91 | N15: 2.89
D17: =AVERAGE(G17,J17,M17) -> 3.4566667 | E17: =AVERAGE(H17,K17,N17) -> 3.9433333 | G17: 3.39 | H17: 3.91 | J17: 3.42 | K17: 3.91 | M17: 3.56 | N17: 4.01

Sheet Overall
C7: 0.1 | F7: 0.2 | I7: 0.3 | L7: 0.4 | O7: 0.5
B8: Clusters | C8: MAE | D8: As Capacity | E8: R-Squared | F8: MAE | G8: As Capacity | H8: R-Squared | I8: MAE | J8: As Capacity | K8: R-Squared | L8: MAE | M8: As Capacity | N8: R-Squared | O8: MAE | P8: As Capacity | Q8: R-Squared
B9: 0 | D9: =AVERAGE(C23:J23) -> 0.051680957 | G9: =AVERAGE(K23:R23) -> 0.043655292 | J9: =AVERAGE(S23:Z23) -> 0.040528671 | M9: =AVERAGE(AA23:AH23) -> 0.038720791 | P9: =AVERAGE(AI23:AP23) -> 0.038003092
B10: 1 | D10: =AVERAGE(C24:J24) -> 0.039790524 | G10: =AVERAGE(K24:R24) -> 0.034114201 | J10: =AVERAGE(S24:Z24) -> 0.031747974 | M10: =AVERAGE(AA24:AH24) -> 0.029429526 | P10: =AVERAGE(AI24:AP24) -> 0.028805375
B11: 2 | D11: =AVERAGE(C25:J25) -> 0.062654952 | G11: =AVERAGE(K25:R25) -> 0.046016493 | J11: =AVERAGE(S25:Z25) -> 0.040882998 | M11: =AVERAGE(AA25:AH25) -> 0.035956198 | P11: =AVERAGE(AI25:AP25) -> 0.034567224
B12: 3 | D12: =AVERAGE(C26:J26) -> 0.051816313 | G12: =AVERAGE(K26:R26) -> 0.042842736 | J12: =AVERAGE(S26:Z26) -> 0.040703252 | M12: =AVERAGE(AA26:AH26) -> 0.037331016 | P12: =AVERAGE(AI26:AP26) -> 0.035883801
B13: 4 | D13: =AVERAGE(C27:J27) -> 0.052969338 | G13: =AVERAGE(K27:R27) -> 0.043841672 | J13: =AVERAGE(S27:Z27) -> 0.039366513 | M13: =AVERAGE(AA27:AH27) -> 0.035831307 | P13: =AVERAGE(AI27:AP27) -> 0.034805426
B14: 5 | D14: =AVERAGE(C28:J28) -> 0.061100208 | G14: =AVERAGE(K28:R28) -> 0.045816061 | J14: =AVERAGE(S28:Z28) -> 0.042916949 | M14: =AVERAGE(AA28:AH28) -> 0.038279873 | P14: =AVERAGE(AI28:AP28) -> 0.036637481
B15: 6 | D15: =AVERAGE(C29:J29) -> 0.074109733 | G15: =AVERAGE(K29:R29) -> 0.052640971 | J15: =AVERAGE(S29:Z29) -> 0.046361457 | M15: =AVERAGE(AA29:AH29) -> 0.041447978 | P15: =AVERAGE(AI29:AP29) -> 0.039980013
B16: 7 | D16: =AVERAGE(C30:J30) -> 0.058621437 | G16: =AVERAGE(K30:R30) -> 0.043968825 | J16: =AVERAGE(S30:Z30) -> 0.039835713 | M16: =AVERAGE(AA30:AH30) -> 0.035445869 | P16: =AVERAGE(AI30:AP30) -> 0.03480634
B18: Average | D18: =AVERAGE(C32:J32) -> 0.053247876 | F18: =AVERAGE(F9:F16) -> #DIV/0! | G18: =AVERAGE(K32:R32) -> 0.042418983 | I18: =AVERAGE(I9:I16) -> #DIV/0! | J18: =AVERAGE(S32:Z32) -> 0.038949853 | L18: =AVERAGE(L9:L16) -> #DIV/0! | M18: =AVERAGE(AA32:AH32) -> #DIV/0! | O18: =AVERAGE(O9:O16) -> #DIV/0! | P18: =AVERAGE(AI32:AP32) -> #DIV/0!
C21: 0.1 | K21: 0.2 | S21: 0.3 | AA21: 0.4 | AI21: 0.5
B22: Clusters | C22: Horns | D22: Seagreen | E22: Gemini | F22: Hollandse | G22: Dieppe | H22: Moray | I22: Kriegers | J22: East.Anglia | K22: Horns | L22: Seagreen | M22: Gemini | N22: Hollandse | O22: Dieppe | P22: Moray | Q22: Kriegers | R22: East.Anglia | S22: Horns | T22: Seagreen | U22: Gemini | V22: Hollandse | W22: Dieppe | X22: Moray | Y22: Kriegers | Z22: East.Anglia | AA22: Horns | AB22: Seagreen | AC22: Gemini | AD22: Hollandse | AE22: Dieppe | AF22: Moray | AG22: Kriegers | AH22: East.Anglia | AI22: Horns | AJ22: Seagreen | AK22: Gemini | AL22: Hollandse | AM22: Dieppe | AN22: Moray | AO22: Kriegers | AP22: East.Anglia
B23: 0 | C23: ='Horns Rev'!E9 -> 0.055869346 | D23: =Seagreen!E9 -> 0.050608974 | E23: =Gemini!E9 -> 0.0715 | F23: =Hollandse_Noord!E9 -> 0.045849802 | G23: =Dieppe!E9 -> 0.048252688 | H23: ='Moray Firth'!E9 -> 0.049381651 | I23: =Kriegers!E9 -> 0.055150463 | J23: ='East Anglia One'!E9 -> 0.036834734 | K23: ='Horns Rev'!I9 -> 0.046805902 | L23: =Seagreen!I9 -> 0.042884615 | M23: =Gemini!I9 -> 0.058277778 | N23: =Hollandse_Noord!I9 -> 0.038427756 | O23: =Dieppe!I9 -> 0.038508065 | P23: ='Moray Firth'!I9 -> 0.044003451 | Q23: =Kriegers!I9 -> 0.04849537 | R23: ='East Anglia One'!I9 -> 0.031839402 | S23: ='Horns Rev'!M9 -> 0.043828539 | T23: =Seagreen!M9 -> 0.038974359 | U23: =Gemini!M9 -> 0.052333333 | V23: =Hollandse_Noord!M9 -> 0.03579271 | W23: =Dieppe!M9 -> 0.037768817 | X23: ='Moray Firth'!M9 -> 0.039459304 | Y23: =Kriegers!M9 -> 0.046006944 | Z23: ='East Anglia One'!M9 -> 0.030065359 | AA23: ='Horns Rev'!Q9 -> 0.04190201 | AB23: =Seagreen!Q9 -> 0.037916667 | AC23: =Gemini!Q9 -> 0.051222222 | AD23: =Hollandse_Noord!Q9 -> 0.035177866 | AE23: =Dieppe!Q9 -> 0.040255376 | AF23: ='Moray Firth'!Q9 -> 0.037791199 | AG23: =Kriegers!Q9 -> 0.045659722 | AH23: ='East Anglia One'!Q9 -> 0.01984127 | AI23: ='Horns Rev'!U9 -> 0.041289023 | AJ23: =Seagreen!U9 -> 0.036634615 | AK23: =Gemini!U9 -> 0.052055556 | AL23: =Hollandse_Noord!U9 -> 0.03407993 | AM23: =Dieppe!U9 -> 0.039650538 | AN23: ='Moray Firth'!U9 -> 0.036583261 | AO23: =Kriegers!U9 -> 0.042303241 | AP23: ='East Anglia One'!U9 -> 0.021428571
B24: 1 | C24: ='Horns Rev'!E10 -> 0.045842638 | D24: =Seagreen!E10 -> 0.040673077 | E24: =Gemini!E10 -> 0.021944444 | F24: =Hollandse_Noord!E10 -> 0.040799297 | G24: =Dieppe!E10 -> 0.044018817 | H24: ='Moray Firth'!E10 -> 0.04998562 | I24: =Kriegers!E10 -> 0.034490741 | J24: ='East Anglia One'!E10 -> 0.040569561 | K24: ='Horns Rev'!I10 -> 0.043346907 | L24: =Seagreen!I10 -> 0.034871795 | M24: =Gemini!I10 -> 0.018944444 | N24: =Hollandse_Noord!I10 -> 0.036012297 | O24: =Dieppe!I10 -> 0.034005376 | P24: ='Moray Firth'!I10 -> 0.040580961 | Q24: =Kriegers!I10 -> 0.028877315 | R24: ='East Anglia One'!I10 -> 0.03627451 | S24: ='Horns Rev'!M10 -> 0.038749507 | T24: =Seagreen!M10 -> 0.032820513 | U24: =Gemini!M10 -> 0.018611111 | V24: =Hollandse_Noord!M10 -> 0.033069829 | W24: =Dieppe!M10 -> 0.029233871 | X24: ='Moray Firth'!M10 -> 0.038107564 | Y24: =Kriegers!M10 -> 0.027256944 | Z24: ='East Anglia One'!M10 -> 0.036134454 | AA24: ='Horns Rev'!Q10 -> 0.039099785 | AB24: =Seagreen!Q10 -> 0.031955128 | AC24: =Gemini!Q10 -> 0.017444444 | AD24: =Hollandse_Noord!Q10 -> 0.031313131 | AE24: =Dieppe!Q10 -> 0.027419355 | AF24: ='Moray Firth'!Q10 -> 0.037503595 | AG24: =Kriegers!Q10 -> 0.026331019 | AH24: ='East Anglia One'!Q10 -> 0.024369748 | AI24: ='Horns Rev'!U10 -> 0.037961382 | AJ24: =Seagreen!U10 -> 0.030673077 | AK24: =Gemini!U10 -> 0.017888889 | AL24: =Hollandse_Noord!U10 -> 0.031620553 | AM24: =Dieppe!U10 -> 0.027419355 | AN24: ='Moray Firth'!U10 -> 0.036180615 | AO24: =Kriegers!U10 -> 0.025636574 | AP24: ='East Anglia One'!U10 -> 0.023062558
B25: 2 | C25: ='Horns Rev'!E11 -> 0.058365077 | D25: =Seagreen!E11 -> 0.072307692 | E25: =Gemini!E11 -> 0.051444444 | F25: =Hollandse_Noord!E11 -> 0.057180501 | G25: =Dieppe!E11 -> 0.093077957 | H25: ='Moray Firth'!E11 -> 0.066321542 | I25: =Kriegers!E11 -> 0.047453704 | J25: ='East Anglia One'!E11 -> 0.055088702 | K25: ='Horns Rev'!I11 -> 0.04015062 | L25: =Seagreen!I11 -> 0.050961538 | M25: =Gemini!I11 -> 0.033777778 | N25: =Hollandse_Noord!I11 -> 0.040711462 | O25: =Dieppe!I11 -> 0.066532258 | P25: ='Moray Firth'!I11 -> 0.050100661 | Q25: =Kriegers!I11 -> 0.037905093 | R25: ='East Anglia One'!I11 -> 0.04799253 | S25: ='Horns Rev'!M11 -> 0.034371032 | T25: =Seagreen!M11 -> 0.043301282 | U25: =Gemini!M11 -> 0.029611111 | V25: =Hollandse_Noord!M11 -> 0.03715415 | W25: =Dieppe!M11 -> 0.06391129 | X25: ='Moray Firth'!M11 -> 0.040954846 | Y25: =Kriegers!M11 -> 0.035416667 | Z25: ='East Anglia One'!M11 -> 0.042343604 | AA25: ='Horns Rev'!Q11 -> 0.033626691 | AB25: =Seagreen!Q11 -> 0.037532051 | AC25: =Gemini!Q11 -> 0.027333333 | AD25: =Hollandse_Noord!Q11 -> 0.035529205 | AE25: =Dieppe!Q11 -> 0.054569892 | AF25: ='Moray Firth'!Q11 -> 0.037992522 | AG25: =Kriegers!Q11 -> 0.034548611 | AH25: ='East Anglia One'!Q11 -> 0.026517274 | AI25: ='Horns Rev'!U11 -> 0.032094225 | AJ25: =Seagreen!U11 -> 0.038461538 | AK25: =Gemini!U11 -> 0.025666667 | AL25: =Hollandse_Noord!U11 -> 0.034299517 | AM25: =Dieppe!U11 -> 0.052217742 | AN25: ='Moray Firth'!U11 -> 0.036180615 | AO25: =Kriegers!U11 -> 0.032407407 | AP25: ='East Anglia One'!U11 -> 0.025210084
B26: 3 | C26: ='Horns Rev'!E12 -> 0.053723893 | D26: =Seagreen!E12 -> 0.0525 | E26: =Gemini!E12 -> 0.037888889 | F26: =Hollandse_Noord!E12 -> 0.051602986 | G26: =Dieppe!E12 -> 0.065860215 | H26: ='Moray Firth'!E12 -> 0.040580961 | I26: =Kriegers!E12 -> 0.06087963 | J26: ='East Anglia One'!E12 -> 0.051493931 | K26: ='Horns Rev'!I12 -> 0.046981041 | L26: =Seagreen!I12 -> 0.042884615 | M26: =Gemini!I12 -> 0.032111111 | N26: =Hollandse_Noord!I12 -> 0.040711462 | O26: =Dieppe!I12 -> 0.05094086 | P26: ='Moray Firth'!I12 -> 0.036036813 | Q26: =Kriegers!I12 -> 0.048958333 | R26: ='East Anglia One'!I12 -> 0.044117647 | S26: ='Horns Rev'!M12 -> 0.044222602 | T26: =Seagreen!M12 -> 0.040865385 | U26: =Gemini!M12 -> 0.031166667 | V26: =Hollandse_Noord!M12 -> 0.039086517 | W26: =Dieppe!M12 -> 0.04811828 | X26: ='Moray Firth'!M12 -> 0.035490365 | Y26: =Kriegers!M12 -> 0.043865741 | Z26: ='East Anglia One'!M12 -> 0.042810458 | AA26: ='Horns Rev'!Q12 -> 0.040763606 | AB26: =Seagreen!Q12 -> 0.039294872 | AC26: =Gemini!Q12 -> 0.029444444 | AD26: =Hollandse_Noord!Q12 -> 0.038120334 | AE26: =Dieppe!Q12 -> 0.046236559 | AF26: ='Moray Firth'!Q12 -> 0.033189531 | AG26: =Kriegers!Q12 -> 0.043634259 | AH26: ='East Anglia One'!Q12 -> 0.027964519 | AI26: ='Horns Rev'!U12 -> 0.040325759 | AJ26: =Seagreen!U12 -> 0.037628205 | AK26: =Gemini!U12 -> 0.028277778 | AL26: =Hollandse_Noord!U12 -> 0.036319719 | AM26: =Dieppe!U12 -> 0.044018817 | AN26: ='Moray Firth'!U12 -> 0.031578947 | AO26: =Kriegers!U12 -> 0.042824074 | AP26: ='East Anglia One'!U12 -> 0.026097106
B27: 4 | C27: ='Horns Rev'!E13 -> 0.054117956 | D27: =Seagreen!E13 -> 0.050833333 | E27: =Gemini!E13 -> 0.047722222 | F27: =Hollandse_Noord!E13 -> 0.04571805 | G27: =Dieppe!E13 -> 0.054166667 | H27: ='Moray Firth'!E13 -> 0.044118493 | I27: =Kriegers!E13 -> 0.070775463 | J27: ='East Anglia One'!E13 -> 0.056302521 | K27: ='Horns Rev'!I13 -> 0.043215552 | L27: =Seagreen!I13 -> 0.043173077 | M27: =Gemini!I13 -> 0.041388889 | N27: =Hollandse_Noord!I13 -> 0.040360123 | O27: =Dieppe!I13 -> 0.044489247 | P27: ='Moray Firth'!I13 -> 0.037244751 | Q27: =Kriegers!I13 -> 0.058564815 | R27: ='East Anglia One'!I13 -> 0.042296919 | S27: ='Horns Rev'!M13 -> 0.038355445 | T27: =Seagreen!M13 -> 0.03974359 | U27: =Gemini!M13 -> 0.037833333 | V27: =Hollandse_Noord!M13 -> 0.034606939 | W27: =Dieppe!M13 -> 0.041599462 | X27: ='Moray Firth'!M13 -> 0.035662928 | Y27: =Kriegers!M13 -> 0.048148148 | Z27: ='East Anglia One'!M13 -> 0.03898226 | AA27: ='Horns Rev'!Q13 -> 0.037129472 | AB27: =Seagreen!Q13 -> 0.037884615 | AC27: =Gemini!Q13 -> 0.035388889 | AD27: =Hollandse_Noord!Q13 -> 0.032630654 | AE27: =Dieppe!Q13 -> 0.041465054 | AF27: ='Moray Firth'!Q13 -> 0.03307449 | AG27: =Kriegers!Q13 -> 0.045081019 | AH27: ='East Anglia One'!Q13 -> 0.023996265 | AI27: ='Horns Rev'!U13 -> 0.036735409 | AJ27: =Seagreen!U13 -> 0.034294872 | AK27: =Gemini!U13 -> 0.032888889 | AL27: =Hollandse_Noord!U13 -> 0.031708388 | AM27: =Dieppe!U13 -> 0.042271505 | AN27: ='Moray Firth'!U13 -> 0.032585562 | AO27: =Kriegers!U13 -> 0.044849537 | AP27: ='East Anglia One'!U13 -> 0.023109244
B28: 5 | C28: ='Horns Rev'!E14 -> 0.053592539 | D28: =Seagreen!E14 -> 0.068589744 | E28: =Gemini!E14 -> 0.079055556 | F28: =Hollandse_Noord!E14 -> 0.04571805 | G28: =Dieppe!E14 -> 0.061827957 | H28: ='Moray Firth'!E14 -> 0.046879494 | I28: =Kriegers!E14 -> 0.074594907 | J28: ='East Anglia One'!E14 -> 0.058543417 | K28: ='Horns Rev'!I14 -> 0.041376593 | L28: =Seagreen!I14 -> 0.044166667 | M28: =Gemini!I14 -> 0.060833333 | N28: =Hollandse_Noord!I14 -> 0.040491875 | O28: =Dieppe!I14 -> 0.047379032 | P28: ='Moray Firth'!I14 -> 0.040293356 | Q28: =Kriegers!I14 -> 0.053472222 | R28: ='East Anglia One'!I14 -> 0.038515406 | S28: ='Horns Rev'!M14 -> 0.040544682 | T28: =Seagreen!M14 -> 0.042083333 | U28: =Gemini!M14 -> 0.054944444 | V28: =Hollandse_Noord!M14 -> 0.035924462 | W28: =Dieppe!M14 -> 0.046975806 | X28: ='Moray Firth'!M14 -> 0.036065574 | Y28: =Kriegers!M14 -> 0.050289352 | Z28: ='East Anglia One'!M14 -> 0.036507937 | AA28: ='Horns Rev'!Q14 -> 0.037698673 | AB28: =Seagreen!Q14 -> 0.037660256 | AC28: =Gemini!Q14 -> 0.047666667 | AD28: =Hollandse_Noord!Q14 -> 0.035529205 | AE28: =Dieppe!Q14 -> 0.044758065 | AF28: ='Moray Firth'!Q14 -> 0.034771355 | AG28: =Kriegers!Q14 -> 0.045138889 | AH28: ='East Anglia One'!Q14 -> 0.023015873 | AI28: ='Horns Rev'!U14 -> 0.037917597 | AJ28: =Seagreen!U14 -> 0.036891026 | AK28: =Gemini!U14 -> 0.046 | AL28: =Hollandse_Noord!U14 -> 0.035090031 | AM28: =Dieppe!U14 -> 0.040927419 | AN28: ='Moray Firth'!U14 -> 0.031837791 | AO28: =Kriegers!U14 -> 0.041840278 | AP28: ='East Anglia One'!U14 -> 0.022595705
B29: 6 | C29: ='Horns Rev'!E15 -> 0.066071194 | D29: =Seagreen!E15 -> 0.10346154 | E29: =Gemini!E15 -> 0.076111111 | F29: =Hollandse_Noord!E15 -> 0.076592007 | G29: =Dieppe!E15 -> 0.076948925 | H29: ='Moray Firth'!E15 -> 0.059706644 | I29: =Kriegers!E15 -> 0.06255787 | J29: ='East Anglia One'!E15 -> 0.071428571 | K29: ='Horns Rev'!I15 -> 0.044135032 | L29: =Seagreen!I15 -> 0.054583333 | M29: =Gemini!I15 -> 0.050777778 | N29: =Hollandse_Noord!I15 -> 0.058278437 | O29: =Dieppe!I15 -> 0.059206989 | P29: ='Moray Firth'!I15 -> 0.051107276 | Q29: =Kriegers!I15 -> 0.048090278 | R29: ='East Anglia One'!I15 -> 0.054948646 | S29: ='Horns Rev'!M15 -> 0.042471212 | T29: =Seagreen!M15 -> 0.049647436 | U29: =Gemini!M15 -> 0.043 | V29: =Hollandse_Noord!M15 -> 0.049187527 | W29: =Dieppe!M15 -> 0.051209677 | X29: ='Moray Firth'!M15 -> 0.044779983 | Y29: =Kriegers!M15 -> 0.044097222 | Z29: ='East Anglia One'!M15 -> 0.046498599 | AA29: ='Horns Rev'!Q15 -> 0.040938745 | AB29: =Seagreen!Q15 -> 0.047980769 | AC29: =Gemini!Q15 -> 0.040944444 | AD29: =Hollandse_Noord!Q15 -> 0.044795784 | AE29: =Dieppe!Q15 -> 0.046505376 | AF29: ='Moray Firth'!Q15 -> 0.040120794 | AG29: =Kriegers!Q15 -> 0.041493056 | AH29: ='East Anglia One'!Q15 -> 0.028804855 | AI29: ='Horns Rev'!U15 -> 0.039318709 | AJ29: =Seagreen!U15 -> 0.044807692 | AK29: =Gemini!U15 -> 0.039888889 | AL29: =Hollandse_Noord!U15 -> 0.042599912 | AM29: =Dieppe!U15 -> 0.045094086 | AN29: ='Moray Firth'!U15 -> 0.040811044 | AO29: =Kriegers!U15 -> 0.040335648 | AP29: ='East Anglia One'!U15 -> 0.026984127
B30: 7 | C30: ='Horns Rev'!E16 -> 0.062962476 | D30: =Seagreen!E16 -> 0.05349359 | E30: =Gemini!E16 -> 0.072388889 | F30: =Hollandse_Noord!E16 -> 0.054194115 | G30: =Dieppe!E16 -> 0.047782258 | H30: ='Moray Firth'!E16 -> 0.049439172 | I30: =Kriegers!E16 -> 0.068113426 | J30: ='East Anglia One'!E16 -> 0.060597572 | K30: ='Horns Rev'!I16 -> 0.045054512 | L30: =Seagreen!I16 -> 0.041346154 | M30: =Gemini!I16 -> 0.057611111 | N30: =Hollandse_Noord!I16 -> 0.040272288 | O30: =Dieppe!I16 -> 0.040927419 | P30: ='Moray Firth'!I16 -> 0.034339948 | Q30: =Kriegers!I16 -> 0.046354167 | R30: ='East Anglia One'!I16 -> 0.045845005 | S30: ='Horns Rev'!M16 -> 0.038793292 | T30: =Seagreen!M16 -> 0.036570513 | U30: =Gemini!M16 -> 0.054 | V30: =Hollandse_Noord!M16 -> 0.035748792 | W30: =Dieppe!M16 -> 0.038104839 | X30: ='Moray Firth'!M16 -> 0.031636468 | Y30: =Kriegers!M16 -> 0.044849537 | Z30: ='East Anglia One'!M16 -> 0.03898226 | AA30: ='Horns Rev'!Q16 -> 0.038530584 | AB30: =Seagreen!Q16 -> 0.033878205 | AC30: =Gemini!Q16 -> 0.048055556 | AD30: =Hollandse_Noord!Q16 -> 0.033552921 | AE30: =Dieppe!Q16 -> 0.037163978 | AF30: ='Moray Firth'!Q16 -> 0.02772505 | AG30: =Kriegers!Q16 -> 0.040104167 | AH30: ='East Anglia One'!Q16 -> 0.024556489 | AI30: ='Horns Rev'!U16 -> 0.037961382 | AJ30: =Seagreen!U16 -> 0.032660256 | AK30: =Gemini!U16 -> 0.045833333 | AL30: =Hollandse_Noord!U16 -> 0.032586737 | AM30: =Dieppe!U16 -> 0.037634409 | AN30: ='Moray Firth'!U16 -> 0.028415301 | AO30: =Kriegers!U16 -> 0.039409722 | AP30: ='East Anglia One'!U16 -> 0.02394958
B32: Overall | C32: ='Horns Rev'!E18 -> 0.055322954 | D32: =Seagreen!E18 -> 0.055742723 | E32: =Gemini!E18 -> 0.051560175 | F32: =Hollandse_Noord!E18 -> 0.050243202 | G32: =Dieppe!E18 -> 0.057233359 | H32: ='Moray Firth'!E18 -> 0.048445192 | I32: =Kriegers!E18 -> 0.05622285 | J32: ='East Anglia One'!E18 -> 0.051212554 | K32: ='Horns Rev'!I18 -> 0.043902864 | L32: =Seagreen!I18 -> 0.042440046 | M32: =Gemini!I18 -> 0.040348253 | N32: =Hollandse_Noord!I18 -> 0.040880073 | O32: =Dieppe!I18 -> 0.045035005 | P32: ='Moray Firth'!I18 -> 0.040611512 | Q32: =Kriegers!I18 -> 0.044633205 | R32: ='East Anglia One'!I18 -> 0.041500909 | S32: ='Horns Rev'!M18 -> 0.040184777 | T32: =Seagreen!M18 -> 0.03917577 | U32: =Gemini!M18 -> 0.036792729 | V32: =Hollandse_Noord!M18 -> 0.036774981 | W32: =Dieppe!M18 -> 0.041863573 | X32: ='Moray Firth'!M18 -> 0.037374674 | Y32: =Kriegers!M18 -> 0.040926396 | Z32: ='East Anglia One'!M18 -> 0.038505923 | AA32: ='Horns Rev'!Q18 -> 0.038732579 | AB32: =Seagreen!Q18 -> 0.037184579 | AC32: =Gemini!Q18 -> 0.034385266 | AD32: =Hollandse_Noord!Q18 -> 0.035125817 | AE32: =Dieppe!Q18 -> 0.040303917 | AF32: ='Moray Firth'!Q18 -> 0.035111637 | AG32: =Kriegers!Q18 -> 0.039099119 | AH32: ='East Anglia One'!Q18 -> #DIV/0! | AI32: ='Horns Rev'!U18 -> 0.037977977 | AJ32: =Seagreen!U18 -> 0.035578946 | AK32: =Gemini!U18 -> 0.033434836 | AL32: =Hollandse_Noord!U18 -> 0.034199995 | AM32: =Dieppe!U18 -> 0.039554848 | AN32: ='Moray Firth'!U18 -> 0.034019729 | AO32: =Kriegers!U18 -> 0.037610505 | AP32: ='East Anglia One'!U18 -> #DIV/0!
C34: #DIV/0! | D34: 0.054315788 | E34: 0.052434719 | F34: 0.049170981 | G34: 0.055652688 | H34: 0.053908487 | I34: 0.055484661 | J34: 0.063569404 | K34: #DIV/0! | L34: 0.043326313 | M34: 0.042875137 | N34: 0.040618168 | O34: 0.045700855 | P34: 0.043443666 | Q34: 0.043568579 | R34: 0.041540576 | S34: #DIV/0! | T34: 0.039559209 | U34: 0.036666585 | V34: 0.038132141 | W34: 0.041761154 | X34: 0.037895313 | Y34: 0.04095502 | Z34: 0.038656948 | AA34: #DIV/0! | AB34: 0.036995531 | AC34: 0.035346873 | AD34: 0.036614091 | AE34: 0.040771621 | AF34: 0.036131693 | AG34: 0.039533164 | AH34: 0.034778793 | AI34: #DIV/0! | AJ34: 0.036111551 | AK34: 0.03369576 | AL34: 0.035087501 | AM34: 0.038759229 | AN34: 0.035033124 | AO34: 0.037398737 | AP34: 0.034361115

Sheet Horns Rev
B3: 17513 | C3: hours | D3: 461 | E3: removed
A4: Horns Rev
A5: 761.3
A7: Average | D7: 0.1 | H7: 0.2 | L7: 0.3 | P7: 0.4 | T7: 0.5
B8: Clusters | C8: Test Points | D8: MAE | E8: As Capacity | F8: R-Squared | G8: Test Points | H8: MAE | I8: As Capacity | J8: R-Squared | K8: Test Points | L8: MAE | M8: As Capacity | N8: R-Squared | O8: Test Points | P8: MAE | Q8: As Capacity | R8: R-Squared | S8: Test Points | T8: MAE | U8: As Capacity | V8: R-Squared
B9: 0 | C9: =AVERAGE(C26,C42,C58) -> 1433.3333 | D9: =AVERAGE(D26,D42,D58) -> 42.533333 | E9: =AVERAGE(E26,E42,E58) -> 0.055869346 | F9: =AVERAGE(F26,F42,F58) -> 0.774 | G9: =AVERAGE(G26,G42,G58) -> 1291.6667 | H9: =AVERAGE(H26,H42,H58) -> 35.633333 | I9: =AVERAGE(I26,I42,I58) -> 0.046805902 | J9: =AVERAGE(J26,J42,J58) -> 0.83733333 | ... V9: =AVERAGE(V26,V42,V58) -> 0.8945
B10: 1 | C10: =AVERAGE(C27,C43,C59) -> 2201.6667 | D10: =AVERAGE(D27,D43,D59) -> 34.9 | E10: =AVERAGE(E27,E43,E59) -> 0.045842638 | F10: =AVERAGE(F27,F43,F59) -> 0.88166667 | G10: =AVERAGE(G27,G43,G59) -> 1943.3333 | H10: =AVERAGE(H27,H43,H59) -> 33 | I10: =AVERAGE(I27,I43,I59) -> 0.043346907 | J10: =AVERAGE(J27,J43,J59) -> 0.884 | ... V10: =AVERAGE(V27,V43,V59) -> 0.89
B11: 2 | C11: =AVERAGE(C28,C44,C60) -> 1498.3333 | D11: =AVERAGE(D28,D44,D60) -> 44.433333 | E11: =AVERAGE(E28,E44,E60) -> 0.058365077 | F11: =AVERAGE(F28,F44,F60) -> 0.95 | G11: =AVERAGE(G28,G44,G60) -> 1351.6667 | H11: =AVERAGE(H28,H44,H60) -> 30.566667 | I11: =AVERAGE(I28,I44,I60) -> 0.04015062 | J11: =AVERAGE(J28,J44,J60) -> 0.975 | ... V11: =AVERAGE(V28,V44,V60) -> 0.9825
B12: 3 | C12: =AVERAGE(C29,C45,C61) -> 1871.6667 | D12: =AVERAGE(D29,D45,D61) -> 40.9 | E12: =AVERAGE(E29,E45,E61) -> 0.053723893 | F12: =AVERAGE(F29,F45,F61) -> 0.902 | G12: =AVERAGE(G29,G45,G61) -> 1698.3333 | H12: =AVERAGE(H29,H45,H61) -> 35.766667 | I12: =AVERAGE(I29,I45,I61) -> 0.046981041 | J12: =AVERAGE(J29,J45,J61) -> 0.92933333 | ... V12: =AVERAGE(V29,V45,V61) -> 0.942
B13: 4 | C13: =AVERAGE(C30,C46,C62) -> 2335 | D13: =AVERAGE(D30,D46,D62) -> 41.2 | E13: =AVERAGE(E30,E46,E62) -> 0.054117956 | F13: =AVERAGE(F30,F46,F62) -> 0.952 | G13: =AVERAGE(G30,G46,G62) -> 2098.3333 | H13: =AVERAGE(H30,H46,H62) -> 32.9 | I13: =AVERAGE(I30,I46,I62) -> 0.043215552 | J13: =AVERAGE(J30,J46,J62) -> 0.96833333 | ... V13: =AVERAGE(V30,V46,V62) -> 0.976
B14: 5 | C14: =AVERAGE(C31,C47,C63) -> 1321.6667 | D14: =AVERAGE(D31,D47,D63) -> 40.8 | E14: =AVERAGE(E31,E47,E63) -> 0.053592539 | F14: =AVERAGE(F31,F47,F63) -> 0.918 | G14: =AVERAGE(G31,G47,G63) -> 1118.3333 | H14: =AVERAGE(H31,H47,H63) -> 31.5 | I14: =AVERAGE(I31,I47,I63) -> 0.041376593 | J14: =AVERAGE(J31,J47,J63) -> 0.94633333 | ... V14: =AVERAGE(V31,V47,V63) -> 0.959
B15: 6 | C15: =AVERAGE(C32,C48,C64) -> 1505 | D15: =AVERAGE(D32,D48,D64) -> 50.3 | E15: =AVERAGE(E32,E48,E64) -> 0.066071194 | F15: =AVERAGE(F32,F48,F64) -> 0.94 | G15: =AVERAGE(G32,G48,G64) -> 1320 | H15: =AVERAGE(H32,H48,H64) -> 33.6 | I15: =AVERAGE(I32,I48,I64) -> 0.044135032 | J15: =AVERAGE(J32,J48,J64) -> 0.97033333 | ... V15: =AVERAGE(V32,V48,V64) -> 0.9725
B16: 7 | C16: =AVERAGE(C33,C49,C65) -> 963.33333 | D16: =AVERAGE(D33,D49,D65) -> 47.933333 | E16: =AVERAGE(E33,E49,E65) -> 0.062962476 | F16: =AVERAGE(F33,F49,F65) -> 0.88566667 | G16: =AVERAGE(G33,G49,G65) -> 848.33333 | H16: =AVERAGE(H33,H49,H65) -> 34.3 | I16: =AVERAGE(I33,I49,I65) -> 0.045054512 | J16: =AVERAGE(J33,J49,J65) -> 0.94233333 | ... V16: =AVERAGE(V33,V49,V65) -> 0.9615
B18: Average | D18: =AVERAGE(D35,D51,D67) -> 42.117365 | E18: =AVERAGE(E35,E51,E67) -> 0.055322954 | F18: =AVERAGE(F35,F51,F67) -> #DIV/0! | G18: =AVERAGE(G35,G51,G67) -> #DIV/0! | H18: =AVERAGE(H35,H51,H67) -> 33.42325 | I18: =AVERAGE(I35,I51,I67) -> 0.043902864 | J18: =AVERAGE(J35,J51,J67) -> #DIV/0! | K18: =AVERAGE(K35,K51,K67) -> #DIV/0! | ... V18: =AVERAGE(V35,V51,V67) -> #DIV/0!
C20: =SUM(C9:C16) -> 13130 | G20: =SUM(G9:G16) -> 11670 | K20: =SUM(K9:K16) -> 10210 | O20: =SUM(O9:O16) -> 8755 | S20: =SUM(S9:S16) -> 7295
C21: =C20/($B$3-$D$3) -> 0.76999765 | G21: =G20/($B$3-$D$3) -> 0.6843772
A24: Seed - 42 | D24: 0.1 | H24: 0.2 | L24: 0.3 | P24: 0.4 | T24: 0.5
B25: Clusters | C25: Test Points | D25: MAE | E25: As Capacity | F25: R-Squared | G25: Test Points | H25: MAE | I25: As Capacity | J25: R-Squared | K25: Test Points | L25: MAE | M25: As Capacity | N25: R-Squared | O25: Test Points | P25: MAE | Q25: As Capacity | R25: R-Squared | S25: Test Points | T25: MAE | U25: As Capacity | V25: R-Squared
B26: 0 | C26: 1520 | D26: 41.9 | E26: =D26/$A$5 -> 0.055037436 | F26: 0.786 | G26: 1365 | H26: 36.2 | I26: =H26/$A$5 -> 0.047550243 | J26: 0.854 | K26: 1340 | L26: 33.9 | M26: =L26/$A$5 -> 0.044529095 | N26: 0.89 | O26: 1185 | P26: 31.7 | Q26: =P26/$A$5 -> 0.041639301 | R26: 0.898 | S26: 1015 | T26: 31.5 | U26: =T26/$A$5 -> 0.041376593
B27: 1 | C27: 2105 | D27: 34.4 | E27: =D27/$A$5 -> 0.045185866 | F27: 0.87 | G27: 1880 | H27: 32.6 | I27: =H27/$A$5 -> 0.04282149 | J27: 0.873 | K27: 1570 | L27: 29.6 | M27: =L27/$A$5 -> 0.038880862 | N27: 0.875 | O27: 1315 | P27: 29.6 | Q27: =P27/$A$5 -> 0.038880862 | R27: 0.865 | S27: 1070 | T27: 30.7 | U27: =T27/$A$5 -> 0.040325759
B28: 2 | C28: 1470 | D28: 50 | E28: =D28/$A$5 -> 0.065677131 | F28: 0.94 | G28: 1335 | H28: 30.5 | I28: =H28/$A$5 -> 0.04006305 | J28: 0.976 | K28: 1150 | L28: 26.5 | M28: =L28/$A$5 -> 0.03480888 | N28: 0.981 | O28: 1015 | P28: 24.7 | Q28: =P28/$A$5 -> 0.032444503 | R28: 0.983 | S28: 805 | T28: 23.7 | U28: =T28/$A$5 -> 0.03113096
B29: 3 | C29: 1960 | D29: 38.2 | E29: =D29/$A$5 -> 0.050177328 | F29: 0.916 | G29: 1715 | H29: 32.7 | I29: =H29/$A$5 -> 0.042952844 | J29: 0.939 | K29: 1465 | L29: 30.6 | M29: =L29/$A$5 -> 0.040194404 | N29: 0.943 | O29: 1195 | P29: 30.4 | Q29: =P29/$A$5 -> 0.039931696 | R29: 0.94 | S29: 995 | T29: 31.1 | U29: =T29/$A$5 -> 0.040851176
B30: 4 | C30: 2350 | D30: 41.6 | E30: =D30/$A$5 -> 0.054643373 | F30: 0.952 | G30: 2085 | H30: 33.1 | I30: =H30/$A$5 -> 0.043478261 | J30: 0.967 | K30: 1805 | L30: 27.5 | M30: =L30/$A$5 -> 0.036122422 | N30: 0.976 | O30: 1565 | P30: 28.6 | Q30: =P30/$A$5 -> 0.037567319 | R30: 0.974 | S30: 1345 | T30: 28.1 | U30: =T30/$A$5 -> 0.036910548
B31: 5 | C31: 1315 | D31: 44.7 | E31: =D31/$A$5 -> 0.058715355 | F31: 0.896 | G31: 1145 | H31: 33.8 | I31: =H31/$A$5 -> 0.044397741 | J31: 0.938 | K31: 1005 | L31: 30.9 | M31: =L31/$A$5 -> 0.040588467 | N31: 0.947 | O31: 900 | P31: 29 | Q31: =P31/$A$5 -> 0.038092736 | R31: 0.955 | S31: 730 | T31: 27.3 | U31: =T31/$A$5 -> 0.035859714
B32: 6 | C32: 1460 | D32: 43.3 | E32: =D32/$A$5 -> 0.056876396 | F32: 0.951 | G32: 1310 | H32: 33.1 | I32: =H32/$A$5 -> 0.043478261 | J32: 0.972 | K32: 1125 | L32: 32.2 | M32: =L32/$A$5 -> 0.042296073 | N32: 0.975 | O32: 950 | P32: 29.5 | Q32: =P32/$A$5 -> 0.038749507 | R32: 0.979 | S32: 815 | T32: 28.2 | U32: =T32/$A$5 -> 0.037041902
B33: 7 | C33: 950 | D33: 46.1 | E33: =D33/$A$5 -> 0.060554315 | F33: 0.893 | G33: 835 | H33: 33.2 | I33: =H33/$A$5 -> 0.043609615 | J33: 0.947 | K33: 750 | L33: 29.8 | M33: =L33/$A$5 -> 0.03914357 | N33: 0.953 | O33: 630 | P33: 30.2 | Q33: =P33/$A$5 -> 0.039668987 | R33: 0.954 | S33: 520 | T33: 31.2 | U33: =T33/$A$5 -> 0.04098253
B35: Average | D35: =SUMPRODUCT(C26:C33,D26:D33)/SUM(C26:C33) -> 41.738423 | E35: =SUMPRODUCT(C26:C33,E26:E33)/SUM(C26:C33) -> 0.054825198 | H35: =SUMPRODUCT(G26:G33,H26:H33)/SUM(G26:G33) -> 33.101671 | I35: =SUMPRODUCT(G26:G33,I26:I33)/SUM(G26:G33) -> 0.043480456 | L35: =SUMPRODUCT(K26:K33,L26:L33)/SUM(K26:K33) -> 30.016552 | M35: =SUMPRODUCT(K26:K33,M26:M33)/SUM(K26:K33) -> 0.039428021 | P35: =SUMPRODUCT(O26:O33,P26:P33)/SUM(O26:O33) -> 29.217247 | Q35: =SUMPRODUCT(O26:O33,Q26:Q33)/SUM(O26:O33) -> 0.0383781 | T35: =SUMPRODUCT(S26:S33,T26:T33)/SUM(S26:S33) -> 29.030158 | U35: =SUMPRODUCT(S26:S33,U26:U33)/SUM(S26:S33) -> 0.038132349
E36: 5.84 | I36: 4.63 | M36: 4.14 | Q36: 4 | U36: 3.83
C37: =SUM(C26:C33) -> 13130 | G37: =SUM(G26:G33) -> 11670 | K37: =SUM(K26:K33) -> 10210 | O37: =SUM(O26:O33) -> 8755 | S37: =SUM(S26:S33) -> 7295
A40: Seed - 63 | D40: 0.1 | H40: 0.2 | L40: 0.3 | P40: 0.4 | T40: 0.5
B41: Clusters | C41: Test Points | D41: MAE | E41: As Capacity | F41: R-Squared | G41: Test Points | H41: MAE | I41: As Capacity | J41: R-Squared | K41: Test Points | L41: MAE | M41: As Capacity | N41: R-Squared | O41: Test Points | P41: MAE | Q41: As Capacity | R41: R-Squared | S41: Test Points | T41: MAE | U41: As Capacity | V41: R-Squared
B42: 0 | C42: 1445 | D42: 37.8 | E42: =D42/$A$5 -> 0.049651911 | F42: 0.8 | G42: 1295 | H42: 36.7 | I42: =H42/$A$5 -> 0.048207014 | J42: 0.822 | K42: 1100 | L42: 30.9 | M42: =L42/$A$5 -> 0.040588467 | N42: 0.868 | O42: 985 | P42: 30.4 | Q42: =P42/$A$5 -> 0.039931696 | R42: 0.872 | S42: 890 | T42: 30.4 | U42: =T42/$A$5 -> 0.039931696 | V42: 0.89
B43: 1 | C43: 2230 | D43: 35.1 | E43: =D43/$A$5 -> 0.046105346 | F43: 0.884 | G43: 1980 | H43: 31.3 | I43: =H43/$A$5 -> 0.041113884 | J43: 0.898 | K43: 1720 | L43: 30.1 | M43: =L43/$A$5 -> 0.039537633 | N43: 0.908 | O43: 1450 | P43: 31.4 | Q43: =P43/$A$5 -> 0.041245238 | R43: 0.898 | S43: 1115 | T43: 27.7 | U43: =T43/$A$5 -> 0.036385131 | V43: 0.907
B44: 2 | C44: 1460 | D44: 37.9 | E44: =D44/$A$5 -> 0.049783265 | F44: 0.964 | G44: 1350 | H44: 29.1 | I44: =H44/$A$5 -> 0.03822409 | J44: 0.976 | K44: 1220 | L44: 25.9 | M44: =L44/$A$5 -> 0.034020754 | N44: 0.98 | O44: 1070 | P44: 26.1 | Q44: =P44/$A$5 -> 0.034283462 | R44: 0.98 | S44: 875 | T44: 25.6 | U44: =T44/$A$5 -> 0.033626691 | V44: 0.98
B45: 3 | C45: 1875 | D45: 40.6 | E45: =D45/$A$5 -> 0.053329831 | F45: 0.909 | G45: 1665 | H45: 35.8 | I45: =H45/$A$5 -> 0.047024826 | J45: 0.925 | K45: 1465 | L45: 36.9 | M45: =L45/$A$5 -> 0.048469723 | N45: 0.923 | O45: 1190 | P45: 31.8 | Q45: =P45/$A$5 -> 0.041770655 | R45: 0.942 | S45: 950 | T45: 31.1 | U45: =T45/$A$5 -> 0.040851176 | V45: 0.943
B46: 4 | C46: 2360 | D46: 37.1 | E46: =D46/$A$5 -> 0.048732431 | F46: 0.96 | G46: 2090 | H46: 31.4 | I46: =H46/$A$5 -> 0.041245238 | J46: 0.971 | K46: 1800 | L46: 29.3 | M46: =L46/$A$5 -> 0.038486799 | N46: 0.973 | O46: 1560 | P46: 28.2 | Q46: =P46/$A$5 -> 0.037041902 | R46: 0.975 | S46: 1345 | T46: 28.2 | U46: =T46/$A$5 -> 0.037041902 | V46: 0.975
B47: 5 | C47: 1340 | D47: 43.1 | E47: =D47/$A$5 -> 0.056613687 | F47: 0.921 | G47: 1090 | H47: 28.1 | I47: =H47/$A$5 -> 0.036910548 | J47: 0.951 | K47: 935 | L47: 29.6 | M47: =L47/$A$5 -> 0.038880862 | N47: 0.942 | O47: 795 | P47: 27.2 | Q47: =P47/$A$5 -> 0.035728359 | R47: 0.948 | S47: 720 | T47: 28.9 | U47: =T47/$A$5 -> 0.037961382 | V47: 0.958
B48: 6 | C48: 1465 | D48: 47.4 | E48: =D48/$A$5 -> 0.06226192 | F48: 0.948 | G48: 1335 | H48: 31 | I48: =H48/$A$5 -> 0.040719821 | J48: 0.971 | K48: 1220 | L48: 29.7 | M48: =L48/$A$5 -> 0.039012216 | N48: 0.974 | O48: 1040 | P48: 30.6 | Q48: =P48/$A$5 -> 0.040194404 | R48: 0.973 | S48: 830 | T48: 31.1 | U48: =T48/$A$5 -> 0.040851176 | V48: 0.972
B49: 7 | C49: 955 | D49: 49.8 | E49: =D49/$A$5 -> 0.065414423 | F49: 0.882 | G49: 865 | H49: 33.5 | I49: =H49/$A$5 -> 0.044003678 | J49: 0.942 | K49: 750 | L49: 29.2 | M49: =L49/$A$5 -> 0.038355445 | N49: 0.955 | O49: 665 | P49: 26.6 | Q49: =P49/$A$5 -> 0.034940234 | R49: 0.958 | S49: 570 | T49: 26.3 | U49: =T49/$A$5 -> 0.034546171 | V49: 0.963
B51: Average | D51: =SUMPRODUCT(C42:C49,D42:D49)/SUM(C42:C49) -> 40.111424 | E51: =SUMPRODUCT(C42:C49,E42:E49)/SUM(C42:C49) -> 0.052688065 | H51: =SUMPRODUCT(G42:G49,H42:H49)/SUM(G42:G49) -> 32.134533 | I51: =SUMPRODUCT(G42:G49,I42:I49)/SUM(G42:G49) -> 0.042210079 | L51: =SUMPRODUCT(K42:K49,L42:L49)/SUM(K42:K49) -> 30.359305 | M51: =SUMPRODUCT(K42:K49,M42:M49)/SUM(K42:K49) -> 0.039878241 | P51: =SUMPRODUCT(O42:O49,P42:P49)/SUM(O42:O49) -> 29.282924 | Q51: =SUMPRODUCT(O42:O49,Q42:Q49)/SUM(O42:O49) -> 0.038464369 | T51: =SUMPRODUCT(S42:S49,T42:T49)/SUM(S42:S49) -> 28.708362 | U51: =SUMPRODUCT(S42:S49,U42:U49)/SUM(S42:S49) -> 0.037709657
...

Sheet Seagreen
B3: 17508 | C3: hours | D3: 412 | E3: removed
A4: Seagreen
A5: 1040
A7: Seed - 84 | D7: 0.1 | H7: 0.2 | L7: 0.3 | P7: 0.4 | T7: 0.5
B8: Clusters | C8: Test Points | D8: MAE | E8: As Capacity | F8: R-Squared | G8: Test Points | H8: MAE | I8: As Capacity | J8: R-Squared | K8: Test Points | L8: MAE | M8: As Capacity | N8: R-Squared | O8: Test Points | P8: MAE | Q8: As Capacity | R8: R-Squared | S8: Test Points | T8: MAE | U8: As Capacity | V8: R-Squared
B9: 0 | C9: =AVERAGE(C26,C41,C57) -> 1605 | D9: =AVERAGE(D26,D41,D57) -> 52.633333 | E9: =AVERAGE(E26,E41,E57) -> 0.050608974 | F9: =AVERAGE(F26,F41,F57) -> 0.794 | G9: =AVERAGE(G26,G41,G57) -> 1608.3333 | H9: =AVERAGE(H26,H41,H57) -> 44.6 | I9: =AVERAGE(I26,I41,I57) -> 0.042884615 | J9: =AVERAGE(J26,J41,J57) -> 0.881 | ... V9: =AVERAGE(V26,V41,V57) -> 0.912
B10: 1 | C10: =AVERAGE(C27,C42,C58) -> 3140 | D10: =AVERAGE(D27,D42,D58) -> 42.3 | E10: =AVERAGE(E27,E42,E58) -> 0.040673077 | F10: =AVERAGE(F27,F42,F58) -> 0.915 | G10: =AVERAGE(G27,G42,G58) -> 2601.6667 | H10: =AVERAGE(H27,H42,H58) -> 36.266667 | I10: =AVERAGE(I27,I42,I58) -> 0.034871795 | J10: =AVERAGE(J27,J42,J58) -> 0.92433333 | ... V10: =AVERAGE(V27,V42,V58) -> 0.93833333
B11: 2 | C11: =AVERAGE(C28,C43,C59) -> 876.66667 | D11: =AVERAGE(D28,D43,D59) -> 75.2 | E11: =AVERAGE(E28,E43,E59) -> 0.072307692 | F11: =AVERAGE(F28,F43,F59) -> 0.92166667 | G11: =AVERAGE(G28,G43,G59) -> 748.33333 | H11: =AVERAGE(H28,H43,H59) -> 53 | I11: =AVERAGE(I28,I43,I59) -> 0.050961538 | J11: =AVERAGE(J28,J43,J59) -> 0.95766667 | ... V11: =AVERAGE(V28,V43,V59) -> 0.974
B12: 3 | C12: =AVERAGE(C29,C44,C60) -> 2733.3333 | D12: =AVERAGE(D29,D44,D60) -> 54.6 | E12: =AVERAGE(E29,E44,E60) -> 0.0525 | F12: =AVERAGE(F29,F44,F60) -> 0.92733333 | G12: =AVERAGE(G29,G44,G60) -> 2363.3333 | H12: =AVERAGE(H29,H44,H60) -> 44.6 | I12: =AVERAGE(I29,I44,I60) -> 0.042884615 | J12: =AVERAGE(J29,J44,J60) -> 0.947 | ... V12: =AVERAGE(V29,V44,V60) -> 0.95766667
B13: 4 | C13: =AVERAGE(C30,C45,C61) -> 1673.3333 | D13: =AVERAGE(D30,D45,D61) -> 52.866667 | E13: =AVERAGE(E30,E45,E61) -> 0.050833333 | F13: =AVERAGE(F30,F45,F61) -> 0.95666667 | G13: =AVERAGE(G30,G45,G61) -> 1516.6667 | H13: =AVERAGE(H30,H45,H61) -> 44.9 | I13: =AVERAGE(I30,I45,I61) -> 0.043173077 | J13: =AVERAGE(J30,J45,J61) -> 0.96766667 | ... V13: =AVERAGE(V30,V45,V61) -> 0.97866667
B14: 5 | C14: =AVERAGE(C31,C46,C62) -> 1106.6667 | D14: =AVERAGE(D31,D46,D62) -> 71.333333 | E14: =AVERAGE(E31,E46,E62) -> 0.068589744 | F14: =AVERAGE(F31,F46,F62) -> 0.82266667 | G14: =AVERAGE(G31,G46,G62) -> 1020 | H14: =AVERAGE(H31,H46,H62) -> 45.933333 | I14: =AVERAGE(I31,I46,I62) -> 0.044166667 | J14: =AVERAGE(J31,J46,J62) -> 0.92333333 | ... V14: =AVERAGE(V31,V46,V62) -> 0.946
B15: 6 | C15: =AVERAGE(C32,C47,C63) -> 925 | D15: =AVERAGE(D32,D47,D63) -> 107.6 | E15: =AVERAGE(E32,E47,E63) -> 0.10346154 | F15: =AVERAGE(F32,F47,F63) -> 0.80066667 | G15: =AVERAGE(G32,G47,G63) -> 806.66667 | H15: =AVERAGE(H32,H47,H63) -> 56.766667 | I15: =AVERAGE(I32,I47,I63) -> 0.054583333 | J15: =AVERAGE(J32,J47,J63) -> 0.948 | ... V15: =AVERAGE(V32,V47,V63) -> 0.964
B16: 7 | C16: =AVERAGE(C33,C48,C64) -> 1065 | D16: =AVERAGE(D33,D48,D64) -> 55.633333 | E16: =AVERAGE(E33,E48,E64) -> 0.05349359 | F16: =AVERAGE(F33,F48,F64) -> 0.945 | G16: =AVERAGE(G33,G48,G64) -> 1000 | H16: =AVERAGE(H33,H48,H64) -> 43 | I16: =AVERAGE(I33,I48,I64) -> 0.041346154 | J16: =AVERAGE(J33,J48,J64) -> 0.96533333 | ... V16: =AVERAGE(V33,V48,V64) -> 0.97833333
B18: Average | D18: =AVERAGE(D35,D50,D66) -> 57.972432 | E18: =AVERAGE(E35,E50,E66) -> 0.055742723 | F18: =AVERAGE(F35,F50,F66) -> #DIV/0! | H18: =AVERAGE(H35,H50,H66) -> 44.137648 | I18: =AVERAGE(I35,I50,I66) -> 0.042440046 | J18: =AVERAGE(J35,J50,J66) -> #DIV/0! | L18: =AVERAGE(L35,L50,L66) -> 40.742801 | M18: =AVERAGE(M35,M50,M66) -> 0.03917577 | N18: =AVERAGE(N35,N50,N66) -> #DIV/0! | P18: =AVERAGE(P35,P50,P66) -> 38.671962 | Q18: =AVERAGE(Q35,Q50,Q66) -> 0.037184579 | R18: =AVERAGE(R35,R50,R66) -> #DIV/0! | T18: =AVERAGE(T35,T50,T66) -> 37.002103 | U18: =AVERAGE(U35,U50,U66) -> 0.035578946 | V18: =AVERAGE(V35,V50,V66) -> #DIV/0!
A24: Seed - 42 | D24: 0.1 | H24: 0.2 | L24: 0.3 | P24: 0.4 | T24: 0.5
B25: Clusters | C25: Test Points | D25: MAE | E25: As Capacity | F25: R-Squared | G25: Test Points | H25: MAE | I25: As Capacity | J25: R-Squared | K25: Test Points | L25: MAE | M25: As Capacity | N25: R-Squared | O25: Test Points | P25: MAE | Q25: As Capacity | R25: R-Squared | S25: Test Points | T25: MAE | U25: As Capacity | V25: R-Squared
B26: 0 | C26: 1430 | D26: 47 | E26: =D26/$A$5 -> 0.045192308 | F26: 0.829 | G26: 1555 | H26: 45.5 | I26: =H26/$A$5 -> 0.04375 | J26: 0.873 | K26: 1430 | L26: 43.4 | M26: =L26/$A$5 -> 0.041730769 | N26: 0.896 | O26: 1195 | P26: 41.2 | Q26: =P26/$A$5 -> 0.039615385 | R26: 0.901 | S26: 1015 | T26: 39.4 | U26: =T26/$A$5 -> 0.037884615 | V26: 0.91
B27: 1 | C27: 3200 | D27: 40.5 | E27: =D27/$A$5 -> 0.038942308 | F27: 0.932 | G27: 2665 | H27: 35.2 | I27: =H27/$A$5 -> 0.033846154 | J27: 0.929 | K27: 2275 | L27: 33.7 | M27: =L27/$A$5 -> 0.032403846 | N27: 0.925 | O27: 1955 | P27: 33.7 | Q27: =P27/$A$5 -> 0.032403846 | R27: 0.935 | S27: 1580 | T27: 31.8 | U27: =T27/$A$5 -> 0.030576923 | V27: 0.942
B28: 2 | C28: 895 | D28: 74.7 | E28: =D28/$A$5 -> 0.071826923 | F28: 0.919 | G28: 750 | H28: 51.8 | I28: =H28/$A$5 -> 0.049807692 | J28: 0.964 | K28: 645 | L28: 46 | M28: =L28/$A$5 -> 0.044230769 | N28: 0.968 | O28: 560 | P28: 39.3 | Q28: =P28/$A$5 -> 0.037788462 | R28: 0.976 | S28: 470 | T28: 39.6 | U28: =T28/$A$5 -> 0.038076923 | V28: 0.974
B29: 3 | C29: 2625 | D29: 50.4 | E29: =D29/$A$5 -> 0.048461538 | F29: 0.935 | G29: 2375 | H29: 42.9 | I29: =H29/$A$5 -> 0.04125 | J29: 0.949 | K29: 2020 | L29: 40.1 | M29: =L29/$A$5 -> 0.038557692 | N29: 0.952 | O29: 1685 | P29: 39.4 | Q29: =P29/$A$5 -> 0.037884615 | R29: 0.956 | S29: 1435 | T29: 38.1 | U29: =T29/$A$5 -> 0.036634615 | V29: 0.958
B30: 4 | C30: 1660 | D30: 62.3 | E30: =D30/$A$5 -> 0.059903846 | F30: 0.94 | G30: 1530 | H30: 50.5 | I30: =H30/$A$5 -> 0.048557692 | J30: 0.959 | K30: 1345 | L30: 47.3 | M30: =L30/$A$5 -> 0.045480769 | N30: 0.963 | O30: 1180 | P30: 39.9 | Q30: =P30/$A$5 -> 0.038365385 | R30: 0.974 | S30: 1020 | T30: 36.2 | U30: =T30/$A$5 -> 0.034807692 | V30: 0.978
B31: 5 | C31: 1210 | D31: 82.2 | E31: =D31/$A$5 -> 0.079038462 | F31: 0.809 | G31: 1005 | H31: 45.4 | I31: =H31/$A$5 -> 0.043653846 | J31: 0.931 | K31: 900 | L31: 45.7 | M31: =L31/$A$5 -> 0.043942308 | N31: 0.936 | O31: 805 | P31: 39.7 | Q31: =P31/$A$5 -> 0.038173077 | R31: 0.947 | S31: 650 | T31: 37.1 | U31: =T31/$A$5 -> 0.035673077 | V31: 0.945
B32: 6 | C32: 1020 | D32: 119 | E32: =D32/$A$5 -> 0.11442308 | F32: 0.824 | G32: 790 | H32: 54.1 | I32: =H32/$A$5 -> 0.052019231 | J32: 0.952 | K32: 705 | L32: 49.7 | M32: =L32/$A$5 -> 0.047788462 | N32: 0.96 | O32: 600 | P32: 45.2 | Q32: =P32/$A$5 -> 0.043461538 | R32: 0.967 | S32: 475 | T32: 45.4 | U32: =T32/$A$5 -> 0.043653846 | V32: 0.968
B33: 7 | C33: 1085 | D33: 52.6 | E33: =D33/$A$5 -> 0.050576923 | F33: 0.952 | G33: 995 | H33: 42 | I33: =H33/$A$5 -> 0.040384615 | J33: 0.966 | K33: 890 | L33: 41 | M33: =L33/$A$5 -> 0.039423077 | N33: 0.969 | O33: 770 | P33: 37.1 | Q33: =P33/$A$5 -> 0.035673077 | R33: 0.976 | S33: 645 | T33: 34.5 | U33: =T33/$A$5 -> 0.033173077 | V33: 0.979
B35: Average | D35: =SUMPRODUCT(C26:C33,D26:D33)/SUM(C26:C33) -> 59.222667 | E35: =SUMPRODUCT(C26:C33,E26:E33)/SUM(C26:C33) -> 0.056944872 | H35: =SUMPRODUCT(G26:G33,H26:H33)/SUM(G26:G33) -> 43.953622 | I35: =SUMPRODUCT(G26:G33,I26:I33)/SUM(G26:G33) -> 0.042263098 | L35: =SUMPRODUCT(K26:K33,L26:L33)/SUM(K26:K33) -> 41.692311 | M35: =SUMPRODUCT(K26:K33,M26:M33)/SUM(K26:K33) -> 0.040088761 | P35: =SUMPRODUCT(O26:O33,P26:P33)/SUM(O26:O33) -> 38.656229 | Q35: =SUMPRODUCT(O26:O33,Q26:Q33)/SUM(O26:O33) -> 0.037169451 | T35: =SUMPRODUCT(S26:S33,T26:T33)/SUM(S26:S33) -> 36.814403 | U35: =SUMPRODUCT(S26:S33,U26:U33)/SUM(S26:S33) -> 0.035398465
E36: 5.42 | I36: 4.13 | M36: 3.96 | Q36: 3.69 | U36: 3.61
C37: =SUM(C26:C33) -> 13125 | G37: =SUM(G26:G33) -> 11665 | K37: =SUM(K26:K33) -> 10210 | O37: =SUM(O26:O33) -> 8750 | S37: =SUM(S26:S33) -> 7290
A39: Seed - 63 | D39: 0.1 | H39: 0.2 | L39: 0.3 | P39: 0.4 | T39: 0.5
B40: Clusters | C40: Test Points | D40: MAE | E40: As Capacity | F40: R-Squared | G40: Test Points | H40: MAE | I40: As Capacity | J40: R-Squared | K40: Test Points | L40: MAE | M40: As Capacity | N40: R-Squared | O40: Test Points | P40: MAE | Q40: As Capacity | R40: R-Squared | S40: Test Points | T40: MAE | U40: As Capacity | V40: R-Squared
B41: 0 | C41: 1790 | D41: 59 | E41: =D41/$A$5 -> 0.056730769 | F41: 0.8 | G41: 1745 | H41: 43.2 | I41: =H41/$A$5 -> 0.041538462 | J41: 0.897 | K41: 1410 | L41: 40.2 | M41: =L41/$A$5 -> 0.038653846 | N41: 0.901 | O41: 1235 | P41: 40.6 | Q41: =P41/$A$5 -> 0.039038462 | R41: 0.903 | S41: 1030 | T41: 38.5 | U41: =T41/$A$5 -> 0.037019231 | V41: 0.91
B42: 1 | C42: 3105 | D42: 41.7 | E42: =D42/$A$5 -> 0.040096154 | F42: 0.896 | G42: 2510 | H42: 34.4 | I42: =H42/$A$5 -> 0.033076923 | J42: 0.922 | K42: 2290 | L42: 34.4 | M42: =L42/$A$5 -> 0.033076923 | N42: 0.933 | O42: 1855 | P42: 32.5 | Q42: =P42/$A$5 -> 0.03125 | R42: 0.935 | S42: 1545 | T42: 31.9 | U42: =T42/$A$5 -> 0.030673077 | V42: 0.93
B43: 2 | C43: 845 | D43: 75.8 | E43: =D43/$A$5 -> 0.072884615 | F43: 0.914 | G43: 715 | H43: 61.4 | I43: =H43/$A$5 -> 0.059038462 | J43: 0.939 | K43: 655 | L43: 48.2 | M43: =L43/$A$5 -> 0.046346154 | N43: 0.966 | O43: 570 | P43: 39.9 | Q43: =P43/$A$5 -> 0.038365385 | R43: 0.975 | S43: 485 | T43: 39.6 | U43: =T43/$A$5 -> 0.038076923 | V43: 0.975
B44: 3 | C44: 2605 | D44: 52 | E44: =D44/$A$5 -> 0.05 | F44: 0.935 | G44: 2425 | H44: 44.5 | I44: =H44/$A$5 -> 0.042788462 | J44: 0.949 | K44: 2075 | L44: 45 | M44: =L44/$A$5 -> 0.043269231 | N44: 0.947 | O44: 1820 | P44: 41.9 | Q44: =P44/$A$5 -> 0.040288462 | R44: 0.957 | S44: 1505 | T44: 39.6 | U44: =T44/$A$5 -> 0.038076923 | V44: 0.957
B45: 4 | C45: 1685 | D45: 41.4 | E45: =D45/$A$5 -> 0.039807692 | F45: 0.975 | G45: 1510 | H45: 43.2 | I45: =H45/$A$5 -> 0.041538462 | J45: 0.973 | K45: 1290 | L45: 39.6 | M45: =L45/$A$5 -> 0.038076923 | N45: 0.978 | O45: 1130 | P45: 41.8 | Q45: =P45/$A$5 -> 0.040192308 | R45: 0.976 | S45: 945 | T45: 35.4 | U45: =T45/$A$5 -> 0.034038462 | V45: 0.98
B46: 5 | C46: 1130 | D46: 67 | E46: =D46/$A$5 -> 0.064423077 | F46: 0.846 | G46: 975 | H46: 48.9 | I46: =H46/$A$5 -> 0.047019231 | J46: 0.905 | K46: 935 | L46: 43.5 | M46: =L46/$A$5 -> 0.041826923 | N46: 0.932 | O46: 775 | P46: 38.9 | Q46: =P46/$A$5 -> 0.037403846 | R46: 0.945 | S46: 655 | T46: 39.8 | U46: =T46/$A$5 -> 0.038269231 | V46: 0.945
B47: 6 | C47: 920 | D47: 91.3 | E47: =D47/$A$5 -> 0.087788462 | F47: 0.889 | G47: 835 | H47: 60.9 | I47: =H47/$A$5 -> 0.058557692 | J47: 0.941 | K47: 730 | L47: 53.4 | M47: =L47/$A$5 -> 0.051346154 | N47: 0.959 | O47: 635 | P47: 53.8 | Q47: =P47/$A$5 -> 0.051730769 | R47: 0.957 | S47: 510 | T47: 47.2 | U47: =T47/$A$5 -> 0.045384615 | V47: 0.967
B48: 7 | C48: 1045 | D48: 52.2 | E48: =D48/$A$5 -> 0.050192308 | F48: 0.954 | G48: 950 | H48: 37.3 | I48: =H48/$A$5 -> 0.035865385 | J48: 0.974 | K48: 825 | L48: 36.2 | M48: =L48/$A$5 -> 0.034807692 | N48: 0.975 | O48: 730 | P48: 35.1 | Q48: =P48/$A$5 -> 0.03375 | R48: 0.976 | S48: 615 | T48: 33.1 | U48: =T48/$A$5 -> 0.031826923 | V48: 0.978
B50: Average | D50: =SUMPRODUCT(C41:C48,D41:D48)/SUM(C41:C48) -> 54.751505 | E50: =SUMPRODUCT(C41:C48,E41:E48)/SUM(C41:C48) -> 0.052645678 | H50: =SUMPRODUCT(G41:G48,H41:H48)/SUM(G41:G48) -> 43.955208 | I50: =SUMPRODUCT(G41:G48,I41:I48)/SUM(G41:G48) -> 0.042264623 | L50: =SUMPRODUCT(K41:K48,L41:L48)/SUM(K41:K48) -> 41.234819 | M50: =SUMPRODUCT(K41:K48,M41:M48)/SUM(K41:K48) -> 0.039648864 | P50: =SUMPRODUCT(O41:O48,P41:P48)/SUM(O41:O48) -> 39.611086 | Q50: =SUMPRODUCT(O41:O48,Q41:Q48)/SUM(O41:O48) -> 0.038087582 | T50: =SUMPRODUCT(S41:S48,T41:T48)/SUM(S41:S48) -> 37.269547 | U50: =SUMPRODUCT(S41:S48,U41:U48)/SUM(S41:S48) -> 0.035836103
E51: 5.44 | I51: 4.45 | M51: 3.96 | Q51: 3.7 | U51: 3.62
C52: =SUM(C41:C48) -> 13125 | G52: =SUM(G41:G48) -> 11665 | K52: =SUM(K41:K48) -> 10210 | O52: =SUM(O41:O48) -> 8750 | S52: =SUM(S41:S48) -> 7290
...

Sheet Gemini
B3: 17516 | C3: hours | D3: 86 | E3: removed
A4: Gemini
A5: 600
D7: 0.1 | H7: 0.2 | L7: 0.3 | P7: 0.4 | T7: 0.5
B8: Clusters | C8: Test Points | D8: MAE | E8: As Capacity | F8: R-Squared | G8: Test Points | H8: MAE | I8: As Capacity | J8: R-Squared | K8: Test Points | L8: MAE | M8: As Capacity | N8: R-Squared | O8: Test Points | P8: MAE | Q8: As Capacity | R8: R-Squared | S8: Test Points | T8: MAE | U8: As Capacity | V8: R-Squared
B9: 0 | C9: =AVERAGE(C26,C42,C58) -> 1430 | D9: =AVERAGE(D26,D42,D58) -> 42.9 | E9: =AVERAGE(E26,E42,E58) -> 0.0715 | F9: =AVERAGE(F26,F42,F58) -> 0.85833333 | G9: =AVERAGE(G26,G42,G58) -> 1271.6667 | H9: =AVERAGE(H26,H42,H58) -> 34.966667 | I9: =AVERAGE(I26,I42,I58) -> 0.058277778 | J9: =AVERAGE(J26,J42,J58) -> 0.90366667 | ... V9: =AVERAGE(V26,V42,V58) -> 0.92566667
B10: 1 | C10: =AVERAGE(C27,C43,C59) -> 2583.3333 | D10: =AVERAGE(D27,D43,D59) -> 13.166667 | E10: =AVERAGE(E27,E43,E59) -> 0.021944444 | F10: =AVERAGE(F27,F43,F59) -> 0.82166667 | G10: =AVERAGE(G27,G43,G59) -> 2323.3333 | H10: =AVERAGE(H27,H43,H59) -> 11.366667 | I10: =AVERAGE(I27,I43,I59) -> 0.018944444 | J10: =AVERAGE(J27,J43,J59) -> 0.858 | ... V10: =AVERAGE(V27,V43,V59) -> 0.85133333
B11: 2 | C11: =AVERAGE(C28,C44,C60) -> 1465 | D11: =AVERAGE(D28,D44,D60) -> 30.866667 | E11: =AVERAGE(E28,E44,E60) -> 0.051444444 | F11: =AVERAGE(F28,F44,F60) -> 0.894 | G11: =AVERAGE(G28,G44,G60) -> 1291.6667 | H11: =AVERAGE(H28,H44,H60) -> 20.266667 | I11: =AVERAGE(I28,I44,I60) -> 0.033777778 | J11: =AVERAGE(J28,J44,J60) -> 0.95866667 | ... V11: =AVERAGE(V28,V44,V60) -> 0.97366667
B12: 3 | C12: =AVERAGE(C29,C45,C61) -> 1938.3333 | D12: =AVERAGE(D29,D45,D61) -> 22.733333 | E12: =AVERAGE(E29,E45,E61) -> 0.037888889 | F12: =AVERAGE(F29,F45,F61) -> 0.83066667 | G12: =AVERAGE(G29,G45,G61) -> 1736.6667 | H12: =AVERAGE(H29,H45,H61) -> 19.266667 | I12: =AVERAGE(I29,I45,I61) -> 0.032111111 | J12: =AVERAGE(J29,J45,J61) -> 0.885 | ... V12: =AVERAGE(V29,V45,V61) -> 0.908
B13: 4 | C13: =AVERAGE(C30,C46,C62) -> 2268.3333 | D13: =AVERAGE(D30,D46,D62) -> 28.633333 | E13: =AVERAGE(E30,E46,E62) -> 0.047722222 | F13: =AVERAGE(F30,F46,F62) -> 0.95133333 | G13: =AVERAGE(G30,G46,G62) -> 2003.3333 | H13: =AVERAGE(H30,H46,H62) -> 24.833333 | I13: =AVERAGE(I30,I46,I62) -> 0.041388889 | J13: =AVERAGE(J30,J46,J62) -> 0.96333333 | ... V13: =AVERAGE(V30,V46,V62) -> 0.97633333
B14: 5 | C14: =AVERAGE(C31,C47,C63) -> 1091.6667 | D14: =AVERAGE(D31,D47,D63) -> 47.433333 | E14: =AVERAGE(E31,E47,E63) -> 0.079055556 | F14: =AVERAGE(F31,F47,F63) -> 0.88166667 | G14: =AVERAGE(G31,G47,G63) -> 970 | H14: =AVERAGE(H31,H47,H63) -> 36.5 | I14: =AVERAGE(I31,I47,I63) -> 0.060833333 | J14: =AVERAGE(J31,J47,J63) -> 0.931 | ... V14: =AVERAGE(V31,V47,V63) -> 0.95933333
B15: 6 | C15: =AVERAGE(C32,C48,C64) -> 1303.3333 | D15: =AVERAGE(D32,D48,D64) -> 45.666667 | E15: =AVERAGE(E32,E48,E64) -> 0.076111111 | F15: =AVERAGE(F32,F48,F64) -> 0.90766667 | G15: =AVERAGE(G32,G48,G64) -> 1148.3333 | H15: =AVERAGE(H32,H48,H64) -> 30.466667 | I15: =AVERAGE(I32,I48,I64) -> 0.050777778 | J15: =AVERAGE(J32,J48,J64) -> 0.95533333 | ... V15: =AVERAGE(V32,V48,V64) -> 0.97166667
B16: 7 | C16: =AVERAGE(C33,C49,C65) -> 1030 | D16: =AVERAGE(D33,D49,D65) -> 43.433333 | E16: =AVERAGE(E33,E49,E65) -> 0.072388889 | F16: =AVERAGE(F33,F49,F65) -> 0.909 | G16: =AVERAGE(G33,G49,G65) -> 910 | H16: =AVERAGE(H33,H49,H65) -> 34.566667 | I16: =AVERAGE(I33,I49,I65) -> 0.057611111 | J16: =AVERAGE(J33,J49,J65) -> 0.93666667 | ... V16: =AVERAGE(V33,V49,V65) -> 0.95966667
B18: Average | D18: =AVERAGE(D35,D51,D67) -> 30.936105 | E18: =AVERAGE(E35,E51,E67) -> 0.051560175 | F18: =AVERAGE(F35,F51,F67) -> #DIV/0! | H18: =AVERAGE(H35,H51,H67) -> 24.208952 | I18: =AVERAGE(I35,I51,I67) -> 0.040348253 | J18: =AVERAGE(J35,J51,J67) -> #DIV/0! | L18: =AVERAGE(L35,L51,L67) -> 22.075637 | M18: =AVERAGE(M35,M51,M67) -> 0.036792729 | N18: =AVERAGE(N35,N51,N67) -> #DIV/0! | P18: =AVERAGE(P35,P51,P67) -> 20.631159 | Q18: =AVERAGE(Q35,Q51,Q67) -> 0.034385266 | R18: =AVERAGE(R35,R51,R67) -> #DIV/0! | T18: =AVERAGE(T35,T51,T67) -> 20.060901 | U18: =AVERAGE(U35,U51,U67) -> 0.033434836 | V18: =AVERAGE(V35,V51,V67) -> #DIV/0!
C20: =SUM(C9:C16) -> 13110 | D20: =SUM(C15:C16) / SUM(C9:C16) -> 0.17798118 | G20: =SUM(G9:G16) -> 11655 | K20: =SUM(K9:K16) -> 10200 | O20: =SUM(O9:O16) -> 8740 | S20: =SUM(S9:S16) -> 7285
C21: =C20/($B$3-$D$3) -> 0.75215146 | G21: =G20/($B$3-$D$3) -> 0.6686747
A24: Seed - 42 | D24: 0.1 | H24: 0.2 | L24: 0.3 | P24: 0.4 | T24: 0.5
B25: Clusters | C25: Test Points | D25: MAE | E25: As Capacity | F25: R-Squared | G25: Test Points | H25: MAE | I25: As Capacity | J25: R-Squared | K25: Test Points | L25: MAE | M25: As Capacity | N25: R-Squared | O25: Test Points | P25: MAE | Q25: As Capacity | R25: R-Squared | S25: Test Points | T25: MAE | U25: As Capacity | V25: R-Squared
B26: 0 | C26: 1315 | D26: 37.4 | E26: =D26/$A$5 -> 0.062333333 | F26: 0.884 | G26: 1190 | H26: 34.6 | I26: =H26/$A$5 -> 0.057666667 | J26: 0.905 | K26: 1090 | L26: 32.6 | M26: =L26/$A$5 -> 0.054333333 | N26: 0.917 | O26: 1040 | P26: 31.8 | Q26: =P26/$A$5 -> 0.053 | R26: 0.921 | S26: 865 | T26: 31 | U26: =T26/$A$5 -> 0.051666667 | V26: 0.927
B27: 1 | C27: 2695 | D27: 13.8 | E27: =D27/$A$5 -> 0.023 | F27: 0.855 | G27: 2435 | H27: 11.8 | I27: =H27/$A$5 -> 0.019666667 | J27: 0.886 | K27: 2085 | L27: 11.5 | M27: =L27/$A$5 -> 0.019166667 | N27: 0.885 | O27: 1700 | P27: 10.1 | Q27: =P27/$A$5 -> 0.016833333 | R27: 0.846 | S27: 1380 | T27: 10.7 | U27: =T27/$A$5 -> 0.017833333 | V27: 0.826
B28: 2 | C28: 1510 | D28: 29.3 | E28: =D28/$A$5 -> 0.048833333 | F28: 0.914 | G28: 1325 | H28: 21 | I28: =H28/$A$5 -> 0.035 | J28: 0.958 | K28: 1140 | L28: 15.5 | M28: =L28/$A$5 -> 0.025833333 | N28: 0.977 | O28: 1015 | P28: 15.9 | Q28: =P28/$A$5 -> 0.0265 | R28: 0.977 | S28: 825 | T28: 16.3 | U28: =T28/$A$5 -> 0.027166667 | V28: 0.973
B29: 3 | C29: 1910 | D29: 23 | E29: =D29/$A$5 -> 0.038333333 | F29: 0.83 | G29: 1680 | H29: 19 | I29: =H29/$A$5 -> 0.031666667 | J29: 0.883 | K29: 1470 | L29: 18.1 | M29: =L29/$A$5 -> 0.030166667 | N29: 0.906 | O29: 1265 | P29: 16.9 | Q29: =P29/$A$5 -> 0.028166667 | R29: 0.91 | S29: 1045 | T29: 15.8 | U29: =T29/$A$5 -> 0.026333333 | V29: 0.92
B30: 4 | C30: 2270 | D30: 28.9 | E30: =D30/$A$5 -> 0.048166667 | F30: 0.95 | G30: 2020 | H30: 25.4 | I30: =H30/$A$5 -> 0.042333333 | J30: 0.962 | K30: 1740 | L30: 21.7 | M30: =L30/$A$5 -> 0.036166667 | N30: 0.97 | O30: 1440 | P30: 20.3 | Q30: =P30/$A$5 -> 0.033833333 | R30: 0.973 | S30: 1220 | T30: 20.4 | U30: =T30/$A$5 -> 0.034 | V30: 0.974
B31: 5 | C31: 1055 | D31: 58.4 | E31: =D31/$A$5 -> 0.097333333 | F31: 0.839 | G31: 945 | H31: 39.7 | I31: =H31/$A$5 -> 0.066166667 | J31: 0.925 | K31: 845 | L31: 33.3 | M31: =L31/$A$5 -> 0.0555 | N31: 0.943 | O31: 745 | P31: 28 | Q31: =P31/$A$5 -> 0.046666667 | R31: 0.96 | S31: 640 | T31: 26.5 | U31: =T31/$A$5 -> 0.044166667 | V31: 0.966
B32: 6 | C32: 1310 | D32: 35.2 | E32: =D32/$A$5 -> 0.058666667 | F32: 0.944 | G32: 1150 | H32: 31.1 | I32: =H32/$A$5 -> 0.051833333 | J32: 0.949 | K32: 1010 | L32: 25.5 | M32: =L32/$A$5 -> 0.0425 | N32: 0.967 | O32: 850 | P32: 25.5 | Q32: =P32/$A$5 -> 0.0425 | R32: 0.965 | S32: 715 | T32: 25 | U32: =T32/$A$5 -> 0.041666667 | V32: 0.967
B33: 7 | C33: 1045 | D33: 39.5 | E33: =D33/$A$5 -> 0.065833333 | F33: 0.926 | G33: 910 | H33: 34.3 | I33: =H33/$A$5 -> 0.057166667 | J33: 0.938 | K33: 820 | L33: 34.2 | M33: =L33/$A$5 -> 0.057 | N33: 0.943 | O33: 685 | P33: 29.9 | Q33: =P33/$A$5 -> 0.049833333 | R33: 0.955 | S33: 595 | T33: 26.8 | U33: =T33/$A$5 -> 0.044666667 | V33: 0.961
B35: Average | D35: =SUMPRODUCT(C26:C33,D26:D33)/SUM(C26:C33) -> 29.68341 | E35: =SUMPRODUCT(C26:C33,E26:E33)/SUM(C26:C33) -> 0.049472349 | H35: =SUMPRODUCT(G26:G33,H26:H33)/SUM(G26:G33) -> 24.492021 | I35: =SUMPRODUCT(G26:G33,I26:I33)/SUM(G26:G33) -> 0.040820034 | L35: =SUMPRODUCT(K26:K33,L26:L33)/SUM(K26:K33) -> 21.910196 | M35: =SUMPRODUCT(K26:K33,M26:M33)/SUM(K26:K33) -> 0.036516993 | P35: =SUMPRODUCT(O26:O33,P26:P33)/SUM(O26:O33) -> 20.595824 | Q35: =SUMPRODUCT(O26:O33,Q26:Q33)/SUM(O26:O33) -> 0.034326373 | T35: =SUMPRODUCT(S26:S33,T26:T33)/SUM(S26:S33) -> 20.207069 | U35: =SUMPRODUCT(S26:S33,U26:U33)/SUM(S26:S33) -> 0.033678449
E36: 5.24 | I36: 4.27 | M36: 3.66 | Q36: 3.56 | U36: 3.36
C37: =SUM(C26:C33) -> 13110 | G37: =SUM(G26:G33) -> 11655 | K37: =SUM(K26:K33) -> 10200 | O37: =SUM(O26:O33) -> 8740 | S37: =SUM(S26:S33) -> 7285
A40: Seed - 63 | D40: 0.1 | H40: 0.2 | L40: 0.3 | P40: 0.4 | T40: 0.5
B41: Clusters | C41: Test Points | D41: MAE | E41: As Capacity | F41: R-Squared | G41: Test Points | H41: MAE | I41: As Capacity | J41: R-Squared | K41: Test Points | L41: MAE | M41: As Capacity | N41: R-Squared | O41: Test Points | P41: MAE | Q41: As Capacity | R41: R-Squared | S41: Test Points | T41: MAE | U41: As Capacity | V41: R-Squared
B42: 0 | C42: 1540 | D42: 46.6 | E42: =D42/$A$5 -> 0.077666667 | F42: 0.845 | G42: 1350 | H42: 35.5 | I42: =H42/$A$5 -> 0.059166667 | J42: 0.903 | K42: 1110 | L42: 30.6 | M42: =L42/$A$5 -> 0.051 | N42: 0.926 | O42: 880 | P42: 30.4 | Q42: =P42/$A$5 -> 0.050666667 | R42: 0.926 | S42: 720 | T42: 30.8 | U42: =T42/$A$5 -> 0.051333333 | V42: 0.931
B43: 1 | C43: 2535 | D43: 12.9 | E43: =D43/$A$5 -> 0.0215 | F43: 0.777 | G43: 2255 | H43: 11.3 | I43: =H43/$A$5 -> 0.018833333 | J43: 0.842 | K43: 1965 | L43: 10.8 | M43: =L43/$A$5 -> 0.018 | N43: 0.851 | O43: 1660 | P43: 10.6 | Q43: =P43/$A$5 -> 0.017666667 | R43: 0.863 | S43: 1350 | T43: 11 | U43: =T43/$A$5 -> 0.018333333 | V43: 0.872
B44: 2 | C44: 1445 | D44: 25.1 | E44: =D44/$A$5 -> 0.041833333 | F44: 0.932 | G44: 1270 | H44: 20.3 | I44: =H44/$A$5 -> 0.033833333 | J44: 0.954 | K44: 1125 | L44: 21.4 | M44: =L44/$A$5 -> 0.035666667 | N44: 0.955 | O44: 985 | P44: 17.9 | Q44: =P44/$A$5 -> 0.029833333 | R44: 0.964 | S44: 845 | T44: 16.3 | U44: =T44/$A$5 -> 0.027166667 | V44: 0.969
B45: 3 | C45: 1885 | D45: 24.9 | E45: =D45/$A$5 -> 0.0415 | F45: 0.786 | G45: 1700 | H45: 19.6 | I45: =H45/$A$5 -> 0.032666667 | J45: 0.887 | K45: 1570 | L45: 19.3 | M45: =L45/$A$5 -> 0.032166667 | N45: 0.886 | O45: 1330 | P45: 18 | Q45: =P45/$A$5 -> 0.03 | R45: 0.896 | S45: 1120 | T45: 16.3 | U45: =T45/$A$5 -> 0.027166667 | V45: 0.91
B46: 4 | C46: 2250 | D46: 27.3 | E46: =D46/$A$5 -> 0.0455 | F46: 0.953 | G46: 1975 | H46: 23.6 | I46: =H46/$A$5 -> 0.039333333 | J46: 0.967 | K46: 1710 | L46: 23.1 | M46: =L46/$A$5 -> 0.0385 | N46: 0.968 | O46: 1515 | P46: 21.7 | Q46: =P46/$A$5 -> 0.036166667 | R46: 0.971 | S46: 1260 | T46: 19.9 | U46: =T46/$A$5 -> 0.033166667 | V46: 0.976
B47: 5 | C47: 1120 | D47: 39.8 | E47: =D47/$A$5 -> 0.066333333 | F47: 0.918 | G47: 975 | H47: 36.5 | I47: =H47/$A$5 -> 0.060833333 | J47: 0.927 | K47: 835 | L47: 32.7 | M47: =L47/$A$5 -> 0.0545 | N47: 0.94 | O47: 710 | P47: 29.1 | Q47: =P47/$A$5 -> 0.0485 | R47: 0.951 | S47: 635 | T47: 28.1 | U47: =T47/$A$5 -> 0.046833333 | V47: 0.954
B48: 6 | C48: 1310 | D48: 47.3 | E48: =D48/$A$5 -> 0.078833333 | F48: 0.903 | G48: 1180 | H48: 28.9 | I48: =H48/$A$5 -> 0.048166667 | J48: 0.962 | K48: 1035 | L48: 26.4 | M48: =L48/$A$5 -> 0.044 | N48: 0.97 | O48: 895 | P48: 25.4 | Q48: =P48/$A$5 -> 0.042333333 | R48: 0.971 | S48: 700 | T48: 23.6 | U48: =T48/$A$5 -> 0.039333333 | V48: 0.975
B49: 7 | C49: 1025 | D49: 44.4 | E49: =D49/$A$5 -> 0.074 | F49: 0.909 | G49: 950 | H49: 36.5 | I49: =H49/$A$5 -> 0.060833333 | J49: 0.933 | K49: 850 | L49: 29.2 | M49: =L49/$A$5 -> 0.048666667 | N49: 0.953 | O49: 765 | P49: 27.9 | Q49: =P49/$A$5 -> 0.0465 | R49: 0.958 | S49: 655 | T49: 28.6 | U49: =T49/$A$5 -> 0.047666667 | V49: 0.955
B51: Average | D51: =SUMPRODUCT(C42:C49,D42:D49)/SUM(C42:C49) -> 30.598436 | E51: =SUMPRODUCT(C42:C49,E42:E49)/SUM(C42:C49) -> 0.050997394 | H51: =SUMPRODUCT(G42:G49,H42:H49)/SUM(G42:G49) -> 24.32278 | I51: =SUMPRODUCT(G42:G49,I42:I49)/SUM(G42:G49) -> 0.040537967 | L51: =SUMPRODUCT(K42:K49,L42:L49)/SUM(K42:K49) -> 22.403284 | M51: =SUMPRODUCT(K42:K49,M42:M49)/SUM(K42:K49) -> 0.037338807 | P51: =SUMPRODUCT(O42:O49,P42:P49)/SUM(O42:O49) -> 20.999142 | Q51: =SUMPRODUCT(O42:O49,Q42:Q49)/SUM(O42:O49) -> 0.03499857 | T51: =SUMPRODUCT(S42:S49,T42:T49)/SUM(S42:S49) -> 20.209472 | U51: =SUMPRODUCT(S42:S49,U42:U49)/SUM(S42:S49) -> 0.033682453
...

Sheet Hollandse_Noord
B3: 17510 | C3: hours | D3: 906 | E3: removed
A4: Hollandse Noord
A5: 759
A7: Seed - 84 | D7: 0.1 | H7: 0.2 | L7: 0.3 | P7: 0.4 | T7: 0.5
B8: Clusters | C8: Test Points | D8: MAE | E8: As Capacity | F8: R-Squared | G8: Test Points | H8: MAE | I8: As Capacity | J8: R-Squared | K8: Test Points | L8: MAE | M8: As Capacity | N8: R-Squared | O8: Test Points | P8: MAE | Q8: As Capacity | R8: R-Squared | S8: Test Points | T8: MAE | U8: As Capacity | V8: R-Squared
B9: 0 | C9: =AVERAGE(C26,C42,C57) -> 1555 | D9: =AVERAGE(D26,D42,D57) -> 34.8 | E9: =AVERAGE(E26,E42,E57) -> 0.045849802 | F9: =AVERAGE(F26,F42,F57) -> 0.83233333 | G9: =AVERAGE(G26,G42,G57) -> 1371.6667 | H9: =AVERAGE(H26,H42,H57) -> 29.166667 | I9: =AVERAGE(I26,I42,I57) -> 0.038427756 | J9: =AVERAGE(J26,J42,J57) -> 0.87966667 | ... V9: =AVERAGE(V26,V42,V57) -> 0.91133333
B10: 1 | C10: =AVERAGE(C27,C43,C58) -> 2643.3333 | D10: =AVERAGE(D27,D43,D58) -> 30.966667 | E10: =AVERAGE(E27,E43,E58) -> 0.040799297 | F10: =AVERAGE(F27,F43,F58) -> 0.88966667 | G10: =AVERAGE(G27,G43,G58) -> 2350 | H10: =AVERAGE(H27,H43,H58) -> 27.333333 | I10: =AVERAGE(I27,I43,I58) -> 0.036012297 | J10: =AVERAGE(J27,J43,J58) -> 0.91166667 | ... V10: =AVERAGE(V27,V43,V58) -> 0.91633333
B11: 2 | C11: =AVERAGE(C28,C44,C59) -> 1306.6667 | D11: =AVERAGE(D28,D44,D59) -> 43.4 | E11: =AVERAGE(E28,E44,E59) -> 0.057180501 | F11: =AVERAGE(F28,F44,F59) -> 0.94666667 | G11: =AVERAGE(G28,G44,G59) -> 1176.6667 | H11: =AVERAGE(H28,H44,H59) -> 30.9 | I11: =AVERAGE(I28,I44,I59) -> 0.040711462 | J11: =AVERAGE(J28,J44,J59) -> 0.96966667 | ... V11: =AVERAGE(V28,V44,V59) -> 0.975
B12: 3 | C12: =AVERAGE(C29,C45,C60) -> 1925 | D12: =AVERAGE(D29,D45,D60) -> 39.166667 | E12: =AVERAGE(E29,E45,E60) -> 0.051602986 | F12: =AVERAGE(F29,F45,F60) -> 0.91433333 | G12: =AVERAGE(G29,G45,G60) -> 1681.6667 | H12: =AVERAGE(H29,H45,H60) -> 30.9 | I12: =AVERAGE(I29,I45,I60) -> 0.040711462 | J12: =AVERAGE(J29,J45,J60) -> 0.942 | ... V12: =AVERAGE(V29,V45,V60) -> 0.95033333
B13: 4 | C13: =AVERAGE(C30,C46,C61) -> 2205 | D13: =AVERAGE(D30,D46,D61) -> 34.7 | E13: =AVERAGE(E30,E46,E61) -> 0.04571805 | F13: =AVERAGE(F30,F46,F61) -> 0.96233333 | G13: =AVERAGE(G30,G46,G61) -> 1973.3333 | H13: =AVERAGE(H30,H46,H61) -> 30.633333 | I13: =AVERAGE(I30,I46,I61) -> 0.040360123 | J13: =AVERAGE(J30,J46,J61) -> 0.96933333 | ... V13: =AVERAGE(V30,V46,V61) -> 0.98033333
B14: 5 | C14: =AVERAGE(C31,C47,C62) -> 1011.6667 | D14: =AVERAGE(D31,D47,D62) -> 34.7 | E14: =AVERAGE(E31,E47,E62) -> 0.04571805 | F14: =AVERAGE(F31,F47,F62) -> 0.909 | G14: =AVERAGE(G31,G47,G62) -> 885 | H14: =AVERAGE(H31,H47,H62) -> 30.733333 | I14: =AVERAGE(I31,I47,I62) -> 0.040491875 | J14: =AVERAGE(J31,J47,J62) -> 0.934 | ... V14: =AVERAGE(V31,V47,V62) -> 0.94466667
B15: 6 | C15: =AVERAGE(C32,C48,C63) -> 1086.6667 | D15: =AVERAGE(D32,D48,D63) -> 58.133333 | E15: =AVERAGE(E32,E48,E63) -> 0.076592007 | F15: =AVERAGE(F32,F48,F63) -> 0.924 | G15: =AVERAGE(G32,G48,G63) -> 973.33333 | H15: =AVERAGE(H32,H48,H63) -> 44.233333 | I15: =AVERAGE(I32,I48,I63) -> 0.058278437 | J15: =AVERAGE(J32,J48,J63) -> 0.95433333 | ... V15: =AVERAGE(V32,V48,V63) -> 0.97166667
B16: 7 | C16: =AVERAGE(C33,C49,C64) -> 1391.6667 | D16: =AVERAGE(D33,D49,D64) -> 41.133333 | E16: =AVERAGE(E33,E49,E64) -> 0.054194115 | F16: =AVERAGE(F33,F49,F64) -> 0.938 | G16: =AVERAGE(G33,G49,G64) -> 1253.3333 | H16: =AVERAGE(H33,H49,H64) -> 30.566667 | I16: =AVERAGE(I33,I49,I64) -> 0.040272288 | J16: =AVERAGE(J33,J49,J64) -> 0.965 | ... V16: =AVERAGE(V33,V49,V64) -> 0.976
